[2024-07-14T09:01:04.877+0000] {local_task_job_runner.py:120} INFO - ::group::Pre task execution logs
[2024-07-14T09:01:04.910+0000] {taskinstance.py:2076} INFO - Dependencies all met for dep_context=non-requeueable deps ti=<TaskInstance: fetch_spread_values.fetch_and_compute_spread_btc_mxn scheduled__2024-07-14T04:36:00+00:00 [queued]>
[2024-07-14T09:01:04.917+0000] {taskinstance.py:2076} INFO - Dependencies all met for dep_context=requeueable deps ti=<TaskInstance: fetch_spread_values.fetch_and_compute_spread_btc_mxn scheduled__2024-07-14T04:36:00+00:00 [queued]>
[2024-07-14T09:01:04.920+0000] {taskinstance.py:2306} INFO - Starting attempt 1 of 2
[2024-07-14T09:01:04.937+0000] {taskinstance.py:2330} INFO - Executing <Task(PythonOperator): fetch_and_compute_spread_btc_mxn> on 2024-07-14 04:36:00+00:00
[2024-07-14T09:01:04.946+0000] {warnings.py:112} WARNING - /home/***/.local/lib/python3.12/site-packages/***/task/task_runner/standard_task_runner.py:61: DeprecationWarning: This process (pid=1812) is multi-threaded, use of fork() may lead to deadlocks in the child.
  pid = os.fork()

[2024-07-14T09:01:04.948+0000] {standard_task_runner.py:63} INFO - Started process 1844 to run task
[2024-07-14T09:01:04.955+0000] {standard_task_runner.py:90} INFO - Running: ['***', 'tasks', 'run', 'fetch_spread_values', 'fetch_and_compute_spread_btc_mxn', 'scheduled__2024-07-14T04:36:00+00:00', '--job-id', '582', '--raw', '--subdir', 'DAGS_FOLDER/***.py', '--cfg-path', '/tmp/tmpenam6zx9']
[2024-07-14T09:01:04.965+0000] {standard_task_runner.py:91} INFO - Job 582: Subtask fetch_and_compute_spread_btc_mxn
[2024-07-14T09:01:05.131+0000] {task_command.py:426} INFO - Running <TaskInstance: fetch_spread_values.fetch_and_compute_spread_btc_mxn scheduled__2024-07-14T04:36:00+00:00 [running]> on host d537c34a4880
[2024-07-14T09:01:05.255+0000] {taskinstance.py:2648} INFO - Exporting env vars: AIRFLOW_CTX_DAG_OWNER='***' AIRFLOW_CTX_DAG_ID='fetch_spread_values' AIRFLOW_CTX_TASK_ID='fetch_and_compute_spread_btc_mxn' AIRFLOW_CTX_EXECUTION_DATE='2024-07-14T04:36:00+00:00' AIRFLOW_CTX_TRY_NUMBER='1' AIRFLOW_CTX_DAG_RUN_ID='scheduled__2024-07-14T04:36:00+00:00'
[2024-07-14T09:01:05.263+0000] {taskinstance.py:430} INFO - ::endgroup::
[2024-07-14T09:01:05.454+0000] {python.py:237} INFO - Done. Returned value was: None
[2024-07-14T09:01:05.459+0000] {taskinstance.py:441} INFO - ::group::Post task execution logs
[2024-07-14T09:01:05.477+0000] {taskinstance.py:1206} INFO - Marking task as SUCCESS. dag_id=fetch_spread_values, task_id=fetch_and_compute_spread_btc_mxn, run_id=scheduled__2024-07-14T04:36:00+00:00, execution_date=20240714T043600, start_date=20240714T090104, end_date=20240714T090105
[2024-07-14T09:01:05.520+0000] {local_task_job_runner.py:240} INFO - Task exited with return code 0
[2024-07-14T09:01:05.538+0000] {taskinstance.py:3503} INFO - 0 downstream tasks scheduled from follow-on schedule check
[2024-07-14T09:01:05.540+0000] {local_task_job_runner.py:222} INFO - ::endgroup::
[2024-07-14T20:34:05.261+0000] {local_task_job_runner.py:120} INFO - ::group::Pre task execution logs
[2024-07-14T20:34:05.290+0000] {taskinstance.py:2076} INFO - Dependencies all met for dep_context=non-requeueable deps ti=<TaskInstance: fetch_spread_values.fetch_and_compute_spread_btc_mxn scheduled__2024-07-14T04:36:00+00:00 [queued]>
[2024-07-14T20:34:05.298+0000] {taskinstance.py:2076} INFO - Dependencies all met for dep_context=requeueable deps ti=<TaskInstance: fetch_spread_values.fetch_and_compute_spread_btc_mxn scheduled__2024-07-14T04:36:00+00:00 [queued]>
[2024-07-14T20:34:05.299+0000] {taskinstance.py:2306} INFO - Starting attempt 1 of 2
[2024-07-14T20:34:05.320+0000] {taskinstance.py:2330} INFO - Executing <Task(PythonOperator): fetch_and_compute_spread_btc_mxn> on 2024-07-14 04:36:00+00:00
[2024-07-14T20:34:05.331+0000] {logging_mixin.py:188} WARNING - /home/***/.local/lib/python3.12/site-packages/***/task/task_runner/standard_task_runner.py:61 DeprecationWarning: This process (pid=1307) is multi-threaded, use of fork() may lead to deadlocks in the child.
[2024-07-14T20:34:05.337+0000] {standard_task_runner.py:63} INFO - Started process 1320 to run task
[2024-07-14T20:34:05.332+0000] {standard_task_runner.py:90} INFO - Running: ['***', 'tasks', 'run', 'fetch_spread_values', 'fetch_and_compute_spread_btc_mxn', 'scheduled__2024-07-14T04:36:00+00:00', '--job-id', '558', '--raw', '--subdir', 'DAGS_FOLDER/***.py', '--cfg-path', '/tmp/tmp4xtrzczb']
[2024-07-14T20:34:05.344+0000] {standard_task_runner.py:91} INFO - Job 558: Subtask fetch_and_compute_spread_btc_mxn
[2024-07-14T20:34:05.394+0000] {task_command.py:426} INFO - Running <TaskInstance: fetch_spread_values.fetch_and_compute_spread_btc_mxn scheduled__2024-07-14T04:36:00+00:00 [running]> on host 77caf7e4b282
[2024-07-14T20:34:05.494+0000] {taskinstance.py:2648} INFO - Exporting env vars: AIRFLOW_CTX_DAG_OWNER='***' AIRFLOW_CTX_DAG_ID='fetch_spread_values' AIRFLOW_CTX_TASK_ID='fetch_and_compute_spread_btc_mxn' AIRFLOW_CTX_EXECUTION_DATE='2024-07-14T04:36:00+00:00' AIRFLOW_CTX_TRY_NUMBER='1' AIRFLOW_CTX_DAG_RUN_ID='scheduled__2024-07-14T04:36:00+00:00'
[2024-07-14T20:34:05.496+0000] {taskinstance.py:430} INFO - ::endgroup::
[2024-07-14T20:34:05.700+0000] {python.py:237} INFO - Done. Returned value was: None
[2024-07-14T20:34:05.707+0000] {taskinstance.py:441} INFO - ::group::Post task execution logs
[2024-07-14T20:34:05.736+0000] {taskinstance.py:1206} INFO - Marking task as SUCCESS. dag_id=fetch_spread_values, task_id=fetch_and_compute_spread_btc_mxn, run_id=scheduled__2024-07-14T04:36:00+00:00, execution_date=20240714T043600, start_date=20240714T203405, end_date=20240714T203405
[2024-07-14T20:34:05.771+0000] {local_task_job_runner.py:240} INFO - Task exited with return code 0
[2024-07-14T20:34:05.792+0000] {local_task_job_runner.py:222} INFO - ::endgroup::
[2024-07-15T06:48:53.985+0000] {local_task_job_runner.py:120} INFO - ::group::Pre task execution logs
[2024-07-15T06:48:54.016+0000] {taskinstance.py:2076} INFO - Dependencies all met for dep_context=non-requeueable deps ti=<TaskInstance: fetch_spread_values.fetch_and_compute_spread_btc_mxn scheduled__2024-07-14T04:36:00+00:00 [queued]>
[2024-07-15T06:48:54.021+0000] {taskinstance.py:2076} INFO - Dependencies all met for dep_context=requeueable deps ti=<TaskInstance: fetch_spread_values.fetch_and_compute_spread_btc_mxn scheduled__2024-07-14T04:36:00+00:00 [queued]>
[2024-07-15T06:48:54.022+0000] {taskinstance.py:2306} INFO - Starting attempt 1 of 2
[2024-07-15T06:48:54.042+0000] {taskinstance.py:2330} INFO - Executing <Task(PythonOperator): fetch_and_compute_spread_btc_mxn> on 2024-07-14 04:36:00+00:00
[2024-07-15T06:48:54.046+0000] {logging_mixin.py:188} WARNING - /home/***/.local/lib/python3.12/site-packages/***/task/task_runner/standard_task_runner.py:61 DeprecationWarning: This process (pid=5806) is multi-threaded, use of fork() may lead to deadlocks in the child.
[2024-07-15T06:48:54.047+0000] {standard_task_runner.py:63} INFO - Started process 5817 to run task
[2024-07-15T06:48:54.048+0000] {standard_task_runner.py:90} INFO - Running: ['***', 'tasks', 'run', 'fetch_spread_values', 'fetch_and_compute_spread_btc_mxn', 'scheduled__2024-07-14T04:36:00+00:00', '--job-id', '1474', '--raw', '--subdir', 'DAGS_FOLDER/et_dag.py', '--cfg-path', '/tmp/tmpp4gh6n7e']
[2024-07-15T06:48:54.049+0000] {standard_task_runner.py:91} INFO - Job 1474: Subtask fetch_and_compute_spread_btc_mxn
[2024-07-15T06:48:54.116+0000] {task_command.py:426} INFO - Running <TaskInstance: fetch_spread_values.fetch_and_compute_spread_btc_mxn scheduled__2024-07-14T04:36:00+00:00 [running]> on host 52e7a9c3d832
[2024-07-15T06:48:54.180+0000] {taskinstance.py:2648} INFO - Exporting env vars: AIRFLOW_CTX_DAG_OWNER='***' AIRFLOW_CTX_DAG_ID='fetch_spread_values' AIRFLOW_CTX_TASK_ID='fetch_and_compute_spread_btc_mxn' AIRFLOW_CTX_EXECUTION_DATE='2024-07-14T04:36:00+00:00' AIRFLOW_CTX_TRY_NUMBER='1' AIRFLOW_CTX_DAG_RUN_ID='scheduled__2024-07-14T04:36:00+00:00'
[2024-07-15T06:48:54.180+0000] {taskinstance.py:430} INFO - ::endgroup::
[2024-07-15T06:48:54.390+0000] {et_dag.py:27} INFO - Data fetched for book btc_mxn
[2024-07-15T06:48:54.399+0000] {et_dag.py:28} INFO - {'success': True, 'payload': {'high': '1119480.00', 'last': '1119480.00', 'created_at': '2024-07-15T06:48:53+00:00', 'book': 'btc_mxn', 'volume': '0', 'vwap': '0', 'low': '1119480.00', 'ask': '1023070.02', 'bid': '1023069.98', 'change_24': '0.00', 'rolling_average_change': {}}}
[2024-07-15T06:48:54.406+0000] {et_dag.py:31} INFO - Spread computed
[2024-07-15T06:48:54.407+0000] {et_dag.py:32} INFO - {'orderbook_timestamp': '2024-07-15T06:48:53+00:00', 'book': 'btc_mxn', 'bid': 1023069.98, 'ask': 1023070.02, 'spread': 3.909800820598076e-06}
[2024-07-15T06:48:54.411+0000] {taskinstance.py:441} INFO - ::group::Post task execution logs
[2024-07-15T06:48:54.421+0000] {taskinstance.py:2905} ERROR - Task failed with exception
Traceback (most recent call last):
  File "/home/airflow/.local/lib/python3.12/site-packages/urllib3/connection.py", line 196, in _new_conn
    sock = connection.create_connection(
           ^^^^^^^^^^^^^^^^^^^^^^^^^^^^^
  File "/home/airflow/.local/lib/python3.12/site-packages/urllib3/util/connection.py", line 85, in create_connection
    raise err
  File "/home/airflow/.local/lib/python3.12/site-packages/urllib3/util/connection.py", line 73, in create_connection
    sock.connect(sa)
ConnectionRefusedError: [Errno 111] Connection refused

The above exception was the direct cause of the following exception:

Traceback (most recent call last):
  File "/home/airflow/.local/lib/python3.12/site-packages/urllib3/connectionpool.py", line 789, in urlopen
    response = self._make_request(
               ^^^^^^^^^^^^^^^^^^^
  File "/home/airflow/.local/lib/python3.12/site-packages/urllib3/connectionpool.py", line 495, in _make_request
    conn.request(
  File "/home/airflow/.local/lib/python3.12/site-packages/urllib3/connection.py", line 398, in request
    self.endheaders()
  File "/usr/local/lib/python3.12/http/client.py", line 1331, in endheaders
    self._send_output(message_body, encode_chunked=encode_chunked)
  File "/usr/local/lib/python3.12/http/client.py", line 1091, in _send_output
    self.send(msg)
  File "/usr/local/lib/python3.12/http/client.py", line 1035, in send
    self.connect()
  File "/home/airflow/.local/lib/python3.12/site-packages/urllib3/connection.py", line 236, in connect
    self.sock = self._new_conn()
                ^^^^^^^^^^^^^^^^
  File "/home/airflow/.local/lib/python3.12/site-packages/urllib3/connection.py", line 211, in _new_conn
    raise NewConnectionError(
urllib3.exceptions.NewConnectionError: <urllib3.connection.HTTPConnection object at 0xffff8de8f7a0>: Failed to establish a new connection: [Errno 111] Connection refused

The above exception was the direct cause of the following exception:

Traceback (most recent call last):
  File "/home/airflow/.local/lib/python3.12/site-packages/requests/adapters.py", line 486, in send
    resp = conn.urlopen(
           ^^^^^^^^^^^^^
  File "/home/airflow/.local/lib/python3.12/site-packages/urllib3/connectionpool.py", line 843, in urlopen
    retries = retries.increment(
              ^^^^^^^^^^^^^^^^^^
  File "/home/airflow/.local/lib/python3.12/site-packages/urllib3/util/retry.py", line 519, in increment
    raise MaxRetryError(_pool, url, reason) from reason  # type: ignore[arg-type]
    ^^^^^^^^^^^^^^^^^^^^^^^^^^^^^^^^^^^^^^^^^^^^^^^^^^^
urllib3.exceptions.MaxRetryError: HTTPConnectionPool(host='127.0.0.1', port=8000): Max retries exceeded with url: /store_spread (Caused by NewConnectionError('<urllib3.connection.HTTPConnection object at 0xffff8de8f7a0>: Failed to establish a new connection: [Errno 111] Connection refused'))

During handling of the above exception, another exception occurred:

Traceback (most recent call last):
  File "/home/airflow/.local/lib/python3.12/site-packages/airflow/models/taskinstance.py", line 465, in _execute_task
    result = _execute_callable(context=context, **execute_callable_kwargs)
             ^^^^^^^^^^^^^^^^^^^^^^^^^^^^^^^^^^^^^^^^^^^^^^^^^^^^^^^^^^^^^
  File "/home/airflow/.local/lib/python3.12/site-packages/airflow/models/taskinstance.py", line 432, in _execute_callable
    return execute_callable(context=context, **execute_callable_kwargs)
           ^^^^^^^^^^^^^^^^^^^^^^^^^^^^^^^^^^^^^^^^^^^^^^^^^^^^^^^^^^^^
  File "/home/airflow/.local/lib/python3.12/site-packages/airflow/models/baseoperator.py", line 401, in wrapper
    return func(self, *args, **kwargs)
           ^^^^^^^^^^^^^^^^^^^^^^^^^^^
  File "/home/airflow/.local/lib/python3.12/site-packages/airflow/operators/python.py", line 235, in execute
    return_value = self.execute_callable()
                   ^^^^^^^^^^^^^^^^^^^^^^^
  File "/home/airflow/.local/lib/python3.12/site-packages/airflow/operators/python.py", line 252, in execute_callable
    return self.python_callable(*self.op_args, **self.op_kwargs)
           ^^^^^^^^^^^^^^^^^^^^^^^^^^^^^^^^^^^^^^^^^^^^^^^^^^^^^
  File "/opt/airflow/dags/et_dag.py", line 34, in trigger_fetch_and_compute
    response = requests.post(URL_STORE_RECORD, headers=HEADERS_JSON, json=spread_record)
               ^^^^^^^^^^^^^^^^^^^^^^^^^^^^^^^^^^^^^^^^^^^^^^^^^^^^^^^^^^^^^^^^^^^^^^^^^
  File "/home/airflow/.local/lib/python3.12/site-packages/requests/api.py", line 115, in post
    return request("post", url, data=data, json=json, **kwargs)
           ^^^^^^^^^^^^^^^^^^^^^^^^^^^^^^^^^^^^^^^^^^^^^^^^^^^^
  File "/home/airflow/.local/lib/python3.12/site-packages/requests/api.py", line 59, in request
    return session.request(method=method, url=url, **kwargs)
           ^^^^^^^^^^^^^^^^^^^^^^^^^^^^^^^^^^^^^^^^^^^^^^^^^
  File "/home/airflow/.local/lib/python3.12/site-packages/requests/sessions.py", line 589, in request
    resp = self.send(prep, **send_kwargs)
           ^^^^^^^^^^^^^^^^^^^^^^^^^^^^^^
  File "/home/airflow/.local/lib/python3.12/site-packages/requests/sessions.py", line 703, in send
    r = adapter.send(request, **kwargs)
        ^^^^^^^^^^^^^^^^^^^^^^^^^^^^^^^
  File "/home/airflow/.local/lib/python3.12/site-packages/requests/adapters.py", line 519, in send
    raise ConnectionError(e, request=request)
requests.exceptions.ConnectionError: HTTPConnectionPool(host='127.0.0.1', port=8000): Max retries exceeded with url: /store_spread (Caused by NewConnectionError('<urllib3.connection.HTTPConnection object at 0xffff8de8f7a0>: Failed to establish a new connection: [Errno 111] Connection refused'))
[2024-07-15T06:48:54.461+0000] {taskinstance.py:1206} INFO - Marking task as UP_FOR_RETRY. dag_id=fetch_spread_values, task_id=fetch_and_compute_spread_btc_mxn, run_id=scheduled__2024-07-14T04:36:00+00:00, execution_date=20240714T043600, start_date=20240715T064854, end_date=20240715T064854
[2024-07-15T06:48:54.543+0000] {standard_task_runner.py:110} ERROR - Failed to execute job 1474 for task fetch_and_compute_spread_btc_mxn (HTTPConnectionPool(host='127.0.0.1', port=8000): Max retries exceeded with url: /store_spread (Caused by NewConnectionError('<urllib3.connection.HTTPConnection object at 0xffff8de8f7a0>: Failed to establish a new connection: [Errno 111] Connection refused')); 5817)
[2024-07-15T06:48:54.560+0000] {local_task_job_runner.py:240} INFO - Task exited with return code 1
[2024-07-15T06:48:54.590+0000] {local_task_job_runner.py:222} INFO - ::endgroup::
