[2024-07-14T08:57:43.839+0000] {local_task_job_runner.py:120} INFO - ::group::Pre task execution logs
[2024-07-14T08:57:43.860+0000] {taskinstance.py:2076} INFO - Dependencies all met for dep_context=non-requeueable deps ti=<TaskInstance: fetch_spread_values.fetch_and_compute_spread_usd_mxn scheduled__2024-07-14T01:01:00+00:00 [queued]>
[2024-07-14T08:57:43.866+0000] {taskinstance.py:2076} INFO - Dependencies all met for dep_context=requeueable deps ti=<TaskInstance: fetch_spread_values.fetch_and_compute_spread_usd_mxn scheduled__2024-07-14T01:01:00+00:00 [queued]>
[2024-07-14T08:57:43.866+0000] {taskinstance.py:2306} INFO - Starting attempt 1 of 2
[2024-07-14T08:57:43.874+0000] {taskinstance.py:2330} INFO - Executing <Task(PythonOperator): fetch_and_compute_spread_usd_mxn> on 2024-07-14 01:01:00+00:00
[2024-07-14T08:57:43.878+0000] {warnings.py:112} WARNING - /home/***/.local/lib/python3.12/site-packages/***/task/task_runner/standard_task_runner.py:61: DeprecationWarning: This process (pid=488) is multi-threaded, use of fork() may lead to deadlocks in the child.
  pid = os.fork()

[2024-07-14T08:57:43.881+0000] {standard_task_runner.py:63} INFO - Started process 511 to run task
[2024-07-14T08:57:43.880+0000] {standard_task_runner.py:90} INFO - Running: ['***', 'tasks', 'run', 'fetch_spread_values', 'fetch_and_compute_spread_usd_mxn', 'scheduled__2024-07-14T01:01:00+00:00', '--job-id', '154', '--raw', '--subdir', 'DAGS_FOLDER/***.py', '--cfg-path', '/tmp/tmpo45jwfed']
[2024-07-14T08:57:43.882+0000] {standard_task_runner.py:91} INFO - Job 154: Subtask fetch_and_compute_spread_usd_mxn
[2024-07-14T08:57:43.912+0000] {task_command.py:426} INFO - Running <TaskInstance: fetch_spread_values.fetch_and_compute_spread_usd_mxn scheduled__2024-07-14T01:01:00+00:00 [running]> on host d537c34a4880
[2024-07-14T08:57:43.965+0000] {taskinstance.py:2648} INFO - Exporting env vars: AIRFLOW_CTX_DAG_OWNER='***' AIRFLOW_CTX_DAG_ID='fetch_spread_values' AIRFLOW_CTX_TASK_ID='fetch_and_compute_spread_usd_mxn' AIRFLOW_CTX_EXECUTION_DATE='2024-07-14T01:01:00+00:00' AIRFLOW_CTX_TRY_NUMBER='1' AIRFLOW_CTX_DAG_RUN_ID='scheduled__2024-07-14T01:01:00+00:00'
[2024-07-14T08:57:43.967+0000] {taskinstance.py:430} INFO - ::endgroup::
[2024-07-14T08:57:44.120+0000] {python.py:237} INFO - Done. Returned value was: None
[2024-07-14T08:57:44.121+0000] {taskinstance.py:441} INFO - ::group::Post task execution logs
[2024-07-14T08:57:44.126+0000] {taskinstance.py:1206} INFO - Marking task as SUCCESS. dag_id=fetch_spread_values, task_id=fetch_and_compute_spread_usd_mxn, run_id=scheduled__2024-07-14T01:01:00+00:00, execution_date=20240714T010100, start_date=20240714T085743, end_date=20240714T085744
[2024-07-14T08:57:44.143+0000] {local_task_job_runner.py:240} INFO - Task exited with return code 0
[2024-07-14T08:57:44.153+0000] {taskinstance.py:3503} INFO - 0 downstream tasks scheduled from follow-on schedule check
[2024-07-14T08:57:44.154+0000] {local_task_job_runner.py:222} INFO - ::endgroup::
[2024-07-14T20:32:28.037+0000] {local_task_job_runner.py:120} INFO - ::group::Pre task execution logs
[2024-07-14T20:32:28.071+0000] {taskinstance.py:2076} INFO - Dependencies all met for dep_context=non-requeueable deps ti=<TaskInstance: fetch_spread_values.fetch_and_compute_spread_usd_mxn scheduled__2024-07-14T01:01:00+00:00 [queued]>
[2024-07-14T20:32:28.096+0000] {taskinstance.py:2076} INFO - Dependencies all met for dep_context=requeueable deps ti=<TaskInstance: fetch_spread_values.fetch_and_compute_spread_usd_mxn scheduled__2024-07-14T01:01:00+00:00 [queued]>
[2024-07-14T20:32:28.099+0000] {taskinstance.py:2306} INFO - Starting attempt 1 of 2
[2024-07-14T20:32:28.138+0000] {taskinstance.py:2330} INFO - Executing <Task(PythonOperator): fetch_and_compute_spread_usd_mxn> on 2024-07-14 01:01:00+00:00
[2024-07-14T20:32:28.146+0000] {logging_mixin.py:188} WARNING - /home/***/.local/lib/python3.12/site-packages/***/task/task_runner/standard_task_runner.py:61 DeprecationWarning: This process (pid=431) is multi-threaded, use of fork() may lead to deadlocks in the child.
[2024-07-14T20:32:28.146+0000] {standard_task_runner.py:90} INFO - Running: ['***', 'tasks', 'run', 'fetch_spread_values', 'fetch_and_compute_spread_usd_mxn', 'scheduled__2024-07-14T01:01:00+00:00', '--job-id', '127', '--raw', '--subdir', 'DAGS_FOLDER/***.py', '--cfg-path', '/tmp/tmpzl97ilwa']
[2024-07-14T20:32:28.153+0000] {standard_task_runner.py:91} INFO - Job 127: Subtask fetch_and_compute_spread_usd_mxn
[2024-07-14T20:32:28.151+0000] {standard_task_runner.py:63} INFO - Started process 442 to run task
[2024-07-14T20:32:28.225+0000] {task_command.py:426} INFO - Running <TaskInstance: fetch_spread_values.fetch_and_compute_spread_usd_mxn scheduled__2024-07-14T01:01:00+00:00 [running]> on host 77caf7e4b282
[2024-07-14T20:32:28.320+0000] {taskinstance.py:2648} INFO - Exporting env vars: AIRFLOW_CTX_DAG_OWNER='***' AIRFLOW_CTX_DAG_ID='fetch_spread_values' AIRFLOW_CTX_TASK_ID='fetch_and_compute_spread_usd_mxn' AIRFLOW_CTX_EXECUTION_DATE='2024-07-14T01:01:00+00:00' AIRFLOW_CTX_TRY_NUMBER='1' AIRFLOW_CTX_DAG_RUN_ID='scheduled__2024-07-14T01:01:00+00:00'
[2024-07-14T20:32:28.321+0000] {taskinstance.py:430} INFO - ::endgroup::
[2024-07-14T20:32:28.514+0000] {python.py:237} INFO - Done. Returned value was: None
[2024-07-14T20:32:28.516+0000] {taskinstance.py:441} INFO - ::group::Post task execution logs
[2024-07-14T20:32:28.526+0000] {taskinstance.py:1206} INFO - Marking task as SUCCESS. dag_id=fetch_spread_values, task_id=fetch_and_compute_spread_usd_mxn, run_id=scheduled__2024-07-14T01:01:00+00:00, execution_date=20240714T010100, start_date=20240714T203228, end_date=20240714T203228
[2024-07-14T20:32:28.551+0000] {local_task_job_runner.py:240} INFO - Task exited with return code 0
[2024-07-14T20:32:28.570+0000] {taskinstance.py:3503} INFO - 0 downstream tasks scheduled from follow-on schedule check
[2024-07-14T20:32:28.576+0000] {local_task_job_runner.py:222} INFO - ::endgroup::
[2024-07-15T06:33:36.046+0000] {local_task_job_runner.py:120} INFO - ::group::Pre task execution logs
[2024-07-15T06:33:36.074+0000] {taskinstance.py:2076} INFO - Dependencies all met for dep_context=non-requeueable deps ti=<TaskInstance: fetch_spread_values.fetch_and_compute_spread_usd_mxn scheduled__2024-07-14T01:01:00+00:00 [queued]>
[2024-07-15T06:33:36.078+0000] {taskinstance.py:2076} INFO - Dependencies all met for dep_context=requeueable deps ti=<TaskInstance: fetch_spread_values.fetch_and_compute_spread_usd_mxn scheduled__2024-07-14T01:01:00+00:00 [queued]>
[2024-07-15T06:33:36.079+0000] {taskinstance.py:2306} INFO - Starting attempt 1 of 2
[2024-07-15T06:33:36.093+0000] {taskinstance.py:2330} INFO - Executing <Task(PythonOperator): fetch_and_compute_spread_usd_mxn> on 2024-07-14 01:01:00+00:00
[2024-07-15T06:33:36.102+0000] {logging_mixin.py:188} WARNING - /home/***/.local/lib/python3.12/site-packages/***/task/task_runner/standard_task_runner.py:61 DeprecationWarning: This process (pid=3235) is multi-threaded, use of fork() may lead to deadlocks in the child.
[2024-07-15T06:33:36.101+0000] {standard_task_runner.py:90} INFO - Running: ['***', 'tasks', 'run', 'fetch_spread_values', 'fetch_and_compute_spread_usd_mxn', 'scheduled__2024-07-14T01:01:00+00:00', '--job-id', '337', '--raw', '--subdir', 'DAGS_FOLDER/et_dag.py', '--cfg-path', '/tmp/tmpw6h_v_ou']
[2024-07-15T06:33:36.104+0000] {standard_task_runner.py:91} INFO - Job 337: Subtask fetch_and_compute_spread_usd_mxn
[2024-07-15T06:33:36.104+0000] {standard_task_runner.py:63} INFO - Started process 3243 to run task
[2024-07-15T06:33:36.183+0000] {task_command.py:426} INFO - Running <TaskInstance: fetch_spread_values.fetch_and_compute_spread_usd_mxn scheduled__2024-07-14T01:01:00+00:00 [running]> on host 52e7a9c3d832
[2024-07-15T06:33:36.252+0000] {taskinstance.py:2648} INFO - Exporting env vars: AIRFLOW_CTX_DAG_OWNER='***' AIRFLOW_CTX_DAG_ID='fetch_spread_values' AIRFLOW_CTX_TASK_ID='fetch_and_compute_spread_usd_mxn' AIRFLOW_CTX_EXECUTION_DATE='2024-07-14T01:01:00+00:00' AIRFLOW_CTX_TRY_NUMBER='1' AIRFLOW_CTX_DAG_RUN_ID='scheduled__2024-07-14T01:01:00+00:00'
[2024-07-15T06:33:36.257+0000] {taskinstance.py:430} INFO - ::endgroup::
[2024-07-15T06:33:36.423+0000] {et_dag.py:27} INFO - Data fetched for book usd_mxn
[2024-07-15T06:33:36.424+0000] {et_dag.py:28} INFO - {'success': True, 'payload': {'high': '18.34', 'last': '18.34', 'created_at': '2024-07-15T06:33:35+00:00', 'book': 'usd_mxn', 'volume': '0', 'vwap': '0', 'low': '18.34', 'ask': '17.61', 'bid': '17.60', 'change_24': '0.00', 'rolling_average_change': {}}}
[2024-07-15T06:33:36.426+0000] {et_dag.py:31} INFO - Spread computed
[2024-07-15T06:33:36.426+0000] {et_dag.py:32} INFO - {'orderbook_timestamp': '2024-07-15T06:33:35+00:00', 'book': 'usd_mxn', 'bid': 17.6, 'ask': 17.61, 'spread': 0.05678591709254975}
[2024-07-15T06:33:36.427+0000] {taskinstance.py:441} INFO - ::group::Post task execution logs
[2024-07-15T06:33:36.429+0000] {taskinstance.py:2905} ERROR - Task failed with exception
Traceback (most recent call last):
  File "/home/airflow/.local/lib/python3.12/site-packages/urllib3/connection.py", line 196, in _new_conn
    sock = connection.create_connection(
           ^^^^^^^^^^^^^^^^^^^^^^^^^^^^^
  File "/home/airflow/.local/lib/python3.12/site-packages/urllib3/util/connection.py", line 85, in create_connection
    raise err
  File "/home/airflow/.local/lib/python3.12/site-packages/urllib3/util/connection.py", line 73, in create_connection
    sock.connect(sa)
ConnectionRefusedError: [Errno 111] Connection refused

The above exception was the direct cause of the following exception:

Traceback (most recent call last):
  File "/home/airflow/.local/lib/python3.12/site-packages/urllib3/connectionpool.py", line 789, in urlopen
    response = self._make_request(
               ^^^^^^^^^^^^^^^^^^^
  File "/home/airflow/.local/lib/python3.12/site-packages/urllib3/connectionpool.py", line 495, in _make_request
    conn.request(
  File "/home/airflow/.local/lib/python3.12/site-packages/urllib3/connection.py", line 398, in request
    self.endheaders()
  File "/usr/local/lib/python3.12/http/client.py", line 1331, in endheaders
    self._send_output(message_body, encode_chunked=encode_chunked)
  File "/usr/local/lib/python3.12/http/client.py", line 1091, in _send_output
    self.send(msg)
  File "/usr/local/lib/python3.12/http/client.py", line 1035, in send
    self.connect()
  File "/home/airflow/.local/lib/python3.12/site-packages/urllib3/connection.py", line 236, in connect
    self.sock = self._new_conn()
                ^^^^^^^^^^^^^^^^
  File "/home/airflow/.local/lib/python3.12/site-packages/urllib3/connection.py", line 211, in _new_conn
    raise NewConnectionError(
urllib3.exceptions.NewConnectionError: <urllib3.connection.HTTPConnection object at 0xffff8dc6c5c0>: Failed to establish a new connection: [Errno 111] Connection refused

The above exception was the direct cause of the following exception:

Traceback (most recent call last):
  File "/home/airflow/.local/lib/python3.12/site-packages/requests/adapters.py", line 486, in send
    resp = conn.urlopen(
           ^^^^^^^^^^^^^
  File "/home/airflow/.local/lib/python3.12/site-packages/urllib3/connectionpool.py", line 843, in urlopen
    retries = retries.increment(
              ^^^^^^^^^^^^^^^^^^
  File "/home/airflow/.local/lib/python3.12/site-packages/urllib3/util/retry.py", line 519, in increment
    raise MaxRetryError(_pool, url, reason) from reason  # type: ignore[arg-type]
    ^^^^^^^^^^^^^^^^^^^^^^^^^^^^^^^^^^^^^^^^^^^^^^^^^^^
urllib3.exceptions.MaxRetryError: HTTPConnectionPool(host='127.0.0.1', port=8000): Max retries exceeded with url: /store_spread (Caused by NewConnectionError('<urllib3.connection.HTTPConnection object at 0xffff8dc6c5c0>: Failed to establish a new connection: [Errno 111] Connection refused'))

During handling of the above exception, another exception occurred:

Traceback (most recent call last):
  File "/home/airflow/.local/lib/python3.12/site-packages/airflow/models/taskinstance.py", line 465, in _execute_task
    result = _execute_callable(context=context, **execute_callable_kwargs)
             ^^^^^^^^^^^^^^^^^^^^^^^^^^^^^^^^^^^^^^^^^^^^^^^^^^^^^^^^^^^^^
  File "/home/airflow/.local/lib/python3.12/site-packages/airflow/models/taskinstance.py", line 432, in _execute_callable
    return execute_callable(context=context, **execute_callable_kwargs)
           ^^^^^^^^^^^^^^^^^^^^^^^^^^^^^^^^^^^^^^^^^^^^^^^^^^^^^^^^^^^^
  File "/home/airflow/.local/lib/python3.12/site-packages/airflow/models/baseoperator.py", line 401, in wrapper
    return func(self, *args, **kwargs)
           ^^^^^^^^^^^^^^^^^^^^^^^^^^^
  File "/home/airflow/.local/lib/python3.12/site-packages/airflow/operators/python.py", line 235, in execute
    return_value = self.execute_callable()
                   ^^^^^^^^^^^^^^^^^^^^^^^
  File "/home/airflow/.local/lib/python3.12/site-packages/airflow/operators/python.py", line 252, in execute_callable
    return self.python_callable(*self.op_args, **self.op_kwargs)
           ^^^^^^^^^^^^^^^^^^^^^^^^^^^^^^^^^^^^^^^^^^^^^^^^^^^^^
  File "/opt/airflow/dags/et_dag.py", line 34, in trigger_fetch_and_compute
    response = requests.post(URL_STORE_RECORD, headers=HEADERS_JSON, json=spread_record)
               ^^^^^^^^^^^^^^^^^^^^^^^^^^^^^^^^^^^^^^^^^^^^^^^^^^^^^^^^^^^^^^^^^^^^^^^^^
  File "/home/airflow/.local/lib/python3.12/site-packages/requests/api.py", line 115, in post
    return request("post", url, data=data, json=json, **kwargs)
           ^^^^^^^^^^^^^^^^^^^^^^^^^^^^^^^^^^^^^^^^^^^^^^^^^^^^
  File "/home/airflow/.local/lib/python3.12/site-packages/requests/api.py", line 59, in request
    return session.request(method=method, url=url, **kwargs)
           ^^^^^^^^^^^^^^^^^^^^^^^^^^^^^^^^^^^^^^^^^^^^^^^^^
  File "/home/airflow/.local/lib/python3.12/site-packages/requests/sessions.py", line 589, in request
    resp = self.send(prep, **send_kwargs)
           ^^^^^^^^^^^^^^^^^^^^^^^^^^^^^^
  File "/home/airflow/.local/lib/python3.12/site-packages/requests/sessions.py", line 703, in send
    r = adapter.send(request, **kwargs)
        ^^^^^^^^^^^^^^^^^^^^^^^^^^^^^^^
  File "/home/airflow/.local/lib/python3.12/site-packages/requests/adapters.py", line 519, in send
    raise ConnectionError(e, request=request)
requests.exceptions.ConnectionError: HTTPConnectionPool(host='127.0.0.1', port=8000): Max retries exceeded with url: /store_spread (Caused by NewConnectionError('<urllib3.connection.HTTPConnection object at 0xffff8dc6c5c0>: Failed to establish a new connection: [Errno 111] Connection refused'))
[2024-07-15T06:33:36.445+0000] {taskinstance.py:1206} INFO - Marking task as UP_FOR_RETRY. dag_id=fetch_spread_values, task_id=fetch_and_compute_spread_usd_mxn, run_id=scheduled__2024-07-14T01:01:00+00:00, execution_date=20240714T010100, start_date=20240715T063336, end_date=20240715T063336
[2024-07-15T06:33:36.454+0000] {standard_task_runner.py:110} ERROR - Failed to execute job 337 for task fetch_and_compute_spread_usd_mxn (HTTPConnectionPool(host='127.0.0.1', port=8000): Max retries exceeded with url: /store_spread (Caused by NewConnectionError('<urllib3.connection.HTTPConnection object at 0xffff8dc6c5c0>: Failed to establish a new connection: [Errno 111] Connection refused')); 3243)
[2024-07-15T06:33:36.491+0000] {local_task_job_runner.py:240} INFO - Task exited with return code 1
[2024-07-15T06:33:36.501+0000] {taskinstance.py:3503} INFO - 0 downstream tasks scheduled from follow-on schedule check
[2024-07-15T06:33:36.502+0000] {local_task_job_runner.py:222} INFO - ::endgroup::
[2024-07-15T07:09:53.107+0000] {local_task_job_runner.py:120} INFO - ::group::Pre task execution logs
[2024-07-15T07:09:53.143+0000] {taskinstance.py:2076} INFO - Dependencies all met for dep_context=non-requeueable deps ti=<TaskInstance: fetch_spread_values.fetch_and_compute_spread_usd_mxn scheduled__2024-07-14T01:01:00+00:00 [queued]>
[2024-07-15T07:09:53.150+0000] {taskinstance.py:2076} INFO - Dependencies all met for dep_context=requeueable deps ti=<TaskInstance: fetch_spread_values.fetch_and_compute_spread_usd_mxn scheduled__2024-07-14T01:01:00+00:00 [queued]>
[2024-07-15T07:09:53.155+0000] {taskinstance.py:2306} INFO - Starting attempt 1 of 2
[2024-07-15T07:09:53.179+0000] {taskinstance.py:2330} INFO - Executing <Task(PythonOperator): fetch_and_compute_spread_usd_mxn> on 2024-07-14 01:01:00+00:00
[2024-07-15T07:09:53.189+0000] {logging_mixin.py:188} WARNING - /home/***/.local/lib/python3.12/site-packages/***/task/task_runner/standard_task_runner.py:61 DeprecationWarning: This process (pid=333) is multi-threaded, use of fork() may lead to deadlocks in the child.
[2024-07-15T07:09:53.196+0000] {standard_task_runner.py:63} INFO - Started process 343 to run task
[2024-07-15T07:09:53.190+0000] {standard_task_runner.py:90} INFO - Running: ['***', 'tasks', 'run', 'fetch_spread_values', 'fetch_and_compute_spread_usd_mxn', 'scheduled__2024-07-14T01:01:00+00:00', '--job-id', '54', '--raw', '--subdir', 'DAGS_FOLDER/et_dag.py', '--cfg-path', '/tmp/tmp_fvb9fd0']
[2024-07-15T07:09:53.202+0000] {standard_task_runner.py:91} INFO - Job 54: Subtask fetch_and_compute_spread_usd_mxn
[2024-07-15T07:09:53.283+0000] {task_command.py:426} INFO - Running <TaskInstance: fetch_spread_values.fetch_and_compute_spread_usd_mxn scheduled__2024-07-14T01:01:00+00:00 [running]> on host 07ee111a4cec
[2024-07-15T07:09:53.382+0000] {taskinstance.py:2648} INFO - Exporting env vars: AIRFLOW_CTX_DAG_OWNER='***' AIRFLOW_CTX_DAG_ID='fetch_spread_values' AIRFLOW_CTX_TASK_ID='fetch_and_compute_spread_usd_mxn' AIRFLOW_CTX_EXECUTION_DATE='2024-07-14T01:01:00+00:00' AIRFLOW_CTX_TRY_NUMBER='1' AIRFLOW_CTX_DAG_RUN_ID='scheduled__2024-07-14T01:01:00+00:00'
[2024-07-15T07:09:53.385+0000] {taskinstance.py:430} INFO - ::endgroup::
[2024-07-15T07:09:53.774+0000] {et_dag.py:27} INFO - Data fetched for book usd_mxn
[2024-07-15T07:09:53.775+0000] {et_dag.py:28} INFO - {'success': True, 'payload': {'high': '18.34', 'last': '18.34', 'created_at': '2024-07-15T07:09:53+00:00', 'book': 'usd_mxn', 'volume': '0', 'vwap': '0', 'low': '18.34', 'ask': '17.61', 'bid': '17.60', 'change_24': '0.00', 'rolling_average_change': {}}}
[2024-07-15T07:09:53.775+0000] {et_dag.py:31} INFO - Spread computed
[2024-07-15T07:09:53.776+0000] {et_dag.py:32} INFO - {'orderbook_timestamp': '2024-07-15T07:09:53+00:00', 'book': 'usd_mxn', 'bid': 17.6, 'ask': 17.61, 'spread': 0.05678591709254975}
[2024-07-15T07:09:53.777+0000] {taskinstance.py:441} INFO - ::group::Post task execution logs
[2024-07-15T07:09:53.778+0000] {taskinstance.py:2905} ERROR - Task failed with exception
Traceback (most recent call last):
  File "/home/airflow/.local/lib/python3.12/site-packages/urllib3/connection.py", line 196, in _new_conn
    sock = connection.create_connection(
           ^^^^^^^^^^^^^^^^^^^^^^^^^^^^^
  File "/home/airflow/.local/lib/python3.12/site-packages/urllib3/util/connection.py", line 85, in create_connection
    raise err
  File "/home/airflow/.local/lib/python3.12/site-packages/urllib3/util/connection.py", line 73, in create_connection
    sock.connect(sa)
ConnectionRefusedError: [Errno 111] Connection refused

The above exception was the direct cause of the following exception:

Traceback (most recent call last):
  File "/home/airflow/.local/lib/python3.12/site-packages/urllib3/connectionpool.py", line 789, in urlopen
    response = self._make_request(
               ^^^^^^^^^^^^^^^^^^^
  File "/home/airflow/.local/lib/python3.12/site-packages/urllib3/connectionpool.py", line 495, in _make_request
    conn.request(
  File "/home/airflow/.local/lib/python3.12/site-packages/urllib3/connection.py", line 398, in request
    self.endheaders()
  File "/usr/local/lib/python3.12/http/client.py", line 1331, in endheaders
    self._send_output(message_body, encode_chunked=encode_chunked)
  File "/usr/local/lib/python3.12/http/client.py", line 1091, in _send_output
    self.send(msg)
  File "/usr/local/lib/python3.12/http/client.py", line 1035, in send
    self.connect()
  File "/home/airflow/.local/lib/python3.12/site-packages/urllib3/connection.py", line 236, in connect
    self.sock = self._new_conn()
                ^^^^^^^^^^^^^^^^
  File "/home/airflow/.local/lib/python3.12/site-packages/urllib3/connection.py", line 211, in _new_conn
    raise NewConnectionError(
urllib3.exceptions.NewConnectionError: <urllib3.connection.HTTPConnection object at 0xffff89dbf7a0>: Failed to establish a new connection: [Errno 111] Connection refused

The above exception was the direct cause of the following exception:

Traceback (most recent call last):
  File "/home/airflow/.local/lib/python3.12/site-packages/requests/adapters.py", line 486, in send
    resp = conn.urlopen(
           ^^^^^^^^^^^^^
  File "/home/airflow/.local/lib/python3.12/site-packages/urllib3/connectionpool.py", line 843, in urlopen
    retries = retries.increment(
              ^^^^^^^^^^^^^^^^^^
  File "/home/airflow/.local/lib/python3.12/site-packages/urllib3/util/retry.py", line 519, in increment
    raise MaxRetryError(_pool, url, reason) from reason  # type: ignore[arg-type]
    ^^^^^^^^^^^^^^^^^^^^^^^^^^^^^^^^^^^^^^^^^^^^^^^^^^^
urllib3.exceptions.MaxRetryError: HTTPConnectionPool(host='127.0.0.1', port=8000): Max retries exceeded with url: /store_spread (Caused by NewConnectionError('<urllib3.connection.HTTPConnection object at 0xffff89dbf7a0>: Failed to establish a new connection: [Errno 111] Connection refused'))

During handling of the above exception, another exception occurred:

Traceback (most recent call last):
  File "/home/airflow/.local/lib/python3.12/site-packages/airflow/models/taskinstance.py", line 465, in _execute_task
    result = _execute_callable(context=context, **execute_callable_kwargs)
             ^^^^^^^^^^^^^^^^^^^^^^^^^^^^^^^^^^^^^^^^^^^^^^^^^^^^^^^^^^^^^
  File "/home/airflow/.local/lib/python3.12/site-packages/airflow/models/taskinstance.py", line 432, in _execute_callable
    return execute_callable(context=context, **execute_callable_kwargs)
           ^^^^^^^^^^^^^^^^^^^^^^^^^^^^^^^^^^^^^^^^^^^^^^^^^^^^^^^^^^^^
  File "/home/airflow/.local/lib/python3.12/site-packages/airflow/models/baseoperator.py", line 401, in wrapper
    return func(self, *args, **kwargs)
           ^^^^^^^^^^^^^^^^^^^^^^^^^^^
  File "/home/airflow/.local/lib/python3.12/site-packages/airflow/operators/python.py", line 235, in execute
    return_value = self.execute_callable()
                   ^^^^^^^^^^^^^^^^^^^^^^^
  File "/home/airflow/.local/lib/python3.12/site-packages/airflow/operators/python.py", line 252, in execute_callable
    return self.python_callable(*self.op_args, **self.op_kwargs)
           ^^^^^^^^^^^^^^^^^^^^^^^^^^^^^^^^^^^^^^^^^^^^^^^^^^^^^
  File "/opt/airflow/dags/et_dag.py", line 34, in trigger_fetch_and_compute
    response = requests.post(URL_STORE_RECORD, headers=HEADERS_JSON, json=spread_record)
               ^^^^^^^^^^^^^^^^^^^^^^^^^^^^^^^^^^^^^^^^^^^^^^^^^^^^^^^^^^^^^^^^^^^^^^^^^
  File "/home/airflow/.local/lib/python3.12/site-packages/requests/api.py", line 115, in post
    return request("post", url, data=data, json=json, **kwargs)
           ^^^^^^^^^^^^^^^^^^^^^^^^^^^^^^^^^^^^^^^^^^^^^^^^^^^^
  File "/home/airflow/.local/lib/python3.12/site-packages/requests/api.py", line 59, in request
    return session.request(method=method, url=url, **kwargs)
           ^^^^^^^^^^^^^^^^^^^^^^^^^^^^^^^^^^^^^^^^^^^^^^^^^
  File "/home/airflow/.local/lib/python3.12/site-packages/requests/sessions.py", line 589, in request
    resp = self.send(prep, **send_kwargs)
           ^^^^^^^^^^^^^^^^^^^^^^^^^^^^^^
  File "/home/airflow/.local/lib/python3.12/site-packages/requests/sessions.py", line 703, in send
    r = adapter.send(request, **kwargs)
        ^^^^^^^^^^^^^^^^^^^^^^^^^^^^^^^
  File "/home/airflow/.local/lib/python3.12/site-packages/requests/adapters.py", line 519, in send
    raise ConnectionError(e, request=request)
requests.exceptions.ConnectionError: HTTPConnectionPool(host='127.0.0.1', port=8000): Max retries exceeded with url: /store_spread (Caused by NewConnectionError('<urllib3.connection.HTTPConnection object at 0xffff89dbf7a0>: Failed to establish a new connection: [Errno 111] Connection refused'))
[2024-07-15T07:09:53.792+0000] {taskinstance.py:1206} INFO - Marking task as UP_FOR_RETRY. dag_id=fetch_spread_values, task_id=fetch_and_compute_spread_usd_mxn, run_id=scheduled__2024-07-14T01:01:00+00:00, execution_date=20240714T010100, start_date=20240715T070953, end_date=20240715T070953
[2024-07-15T07:09:53.798+0000] {standard_task_runner.py:110} ERROR - Failed to execute job 54 for task fetch_and_compute_spread_usd_mxn (HTTPConnectionPool(host='127.0.0.1', port=8000): Max retries exceeded with url: /store_spread (Caused by NewConnectionError('<urllib3.connection.HTTPConnection object at 0xffff89dbf7a0>: Failed to establish a new connection: [Errno 111] Connection refused')); 343)
[2024-07-15T07:09:53.838+0000] {local_task_job_runner.py:240} INFO - Task exited with return code 1
[2024-07-15T07:09:53.848+0000] {taskinstance.py:3503} INFO - 0 downstream tasks scheduled from follow-on schedule check
[2024-07-15T07:09:53.849+0000] {local_task_job_runner.py:222} INFO - ::endgroup::
