[2024-07-14T09:01:03.223+0000] {local_task_job_runner.py:120} INFO - ::group::Pre task execution logs
[2024-07-14T09:01:03.261+0000] {taskinstance.py:2076} INFO - Dependencies all met for dep_context=non-requeueable deps ti=<TaskInstance: fetch_spread_values.fetch_and_compute_spread_usd_mxn scheduled__2024-07-14T04:33:00+00:00 [queued]>
[2024-07-14T09:01:03.295+0000] {taskinstance.py:2076} INFO - Dependencies all met for dep_context=requeueable deps ti=<TaskInstance: fetch_spread_values.fetch_and_compute_spread_usd_mxn scheduled__2024-07-14T04:33:00+00:00 [queued]>
[2024-07-14T09:01:03.296+0000] {taskinstance.py:2306} INFO - Starting attempt 1 of 2
[2024-07-14T09:01:03.327+0000] {taskinstance.py:2330} INFO - Executing <Task(PythonOperator): fetch_and_compute_spread_usd_mxn> on 2024-07-14 04:33:00+00:00
[2024-07-14T09:01:03.347+0000] {warnings.py:112} WARNING - /home/***/.local/lib/python3.12/site-packages/***/task/task_runner/standard_task_runner.py:61: DeprecationWarning: This process (pid=1803) is multi-threaded, use of fork() may lead to deadlocks in the child.
  pid = os.fork()

[2024-07-14T09:01:03.357+0000] {standard_task_runner.py:63} INFO - Started process 1825 to run task
[2024-07-14T09:01:03.354+0000] {standard_task_runner.py:90} INFO - Running: ['***', 'tasks', 'run', 'fetch_spread_values', 'fetch_and_compute_spread_usd_mxn', 'scheduled__2024-07-14T04:33:00+00:00', '--job-id', '574', '--raw', '--subdir', 'DAGS_FOLDER/***.py', '--cfg-path', '/tmp/tmp1oe0s6bf']
[2024-07-14T09:01:03.369+0000] {standard_task_runner.py:91} INFO - Job 574: Subtask fetch_and_compute_spread_usd_mxn
[2024-07-14T09:01:03.526+0000] {task_command.py:426} INFO - Running <TaskInstance: fetch_spread_values.fetch_and_compute_spread_usd_mxn scheduled__2024-07-14T04:33:00+00:00 [running]> on host d537c34a4880
[2024-07-14T09:01:03.804+0000] {taskinstance.py:2648} INFO - Exporting env vars: AIRFLOW_CTX_DAG_OWNER='***' AIRFLOW_CTX_DAG_ID='fetch_spread_values' AIRFLOW_CTX_TASK_ID='fetch_and_compute_spread_usd_mxn' AIRFLOW_CTX_EXECUTION_DATE='2024-07-14T04:33:00+00:00' AIRFLOW_CTX_TRY_NUMBER='1' AIRFLOW_CTX_DAG_RUN_ID='scheduled__2024-07-14T04:33:00+00:00'
[2024-07-14T09:01:03.806+0000] {taskinstance.py:430} INFO - ::endgroup::
[2024-07-14T09:01:04.065+0000] {python.py:237} INFO - Done. Returned value was: None
[2024-07-14T09:01:04.075+0000] {taskinstance.py:441} INFO - ::group::Post task execution logs
[2024-07-14T09:01:04.096+0000] {taskinstance.py:1206} INFO - Marking task as SUCCESS. dag_id=fetch_spread_values, task_id=fetch_and_compute_spread_usd_mxn, run_id=scheduled__2024-07-14T04:33:00+00:00, execution_date=20240714T043300, start_date=20240714T090103, end_date=20240714T090104
[2024-07-14T09:01:04.191+0000] {local_task_job_runner.py:240} INFO - Task exited with return code 0
[2024-07-14T09:01:04.253+0000] {taskinstance.py:3503} INFO - 0 downstream tasks scheduled from follow-on schedule check
[2024-07-14T09:01:04.262+0000] {local_task_job_runner.py:222} INFO - ::endgroup::
[2024-07-14T20:34:01.932+0000] {local_task_job_runner.py:120} INFO - ::group::Pre task execution logs
[2024-07-14T20:34:01.949+0000] {taskinstance.py:2076} INFO - Dependencies all met for dep_context=non-requeueable deps ti=<TaskInstance: fetch_spread_values.fetch_and_compute_spread_usd_mxn scheduled__2024-07-14T04:33:00+00:00 [queued]>
[2024-07-14T20:34:01.953+0000] {taskinstance.py:2076} INFO - Dependencies all met for dep_context=requeueable deps ti=<TaskInstance: fetch_spread_values.fetch_and_compute_spread_usd_mxn scheduled__2024-07-14T04:33:00+00:00 [queued]>
[2024-07-14T20:34:01.955+0000] {taskinstance.py:2306} INFO - Starting attempt 1 of 2
[2024-07-14T20:34:01.964+0000] {taskinstance.py:2330} INFO - Executing <Task(PythonOperator): fetch_and_compute_spread_usd_mxn> on 2024-07-14 04:33:00+00:00
[2024-07-14T20:34:01.968+0000] {logging_mixin.py:188} WARNING - /home/***/.local/lib/python3.12/site-packages/***/task/task_runner/standard_task_runner.py:61 DeprecationWarning: This process (pid=1297) is multi-threaded, use of fork() may lead to deadlocks in the child.
[2024-07-14T20:34:01.968+0000] {standard_task_runner.py:63} INFO - Started process 1302 to run task
[2024-07-14T20:34:01.969+0000] {standard_task_runner.py:90} INFO - Running: ['***', 'tasks', 'run', 'fetch_spread_values', 'fetch_and_compute_spread_usd_mxn', 'scheduled__2024-07-14T04:33:00+00:00', '--job-id', '549', '--raw', '--subdir', 'DAGS_FOLDER/***.py', '--cfg-path', '/tmp/tmpftm_yxh9']
[2024-07-14T20:34:01.970+0000] {standard_task_runner.py:91} INFO - Job 549: Subtask fetch_and_compute_spread_usd_mxn
[2024-07-14T20:34:01.996+0000] {task_command.py:426} INFO - Running <TaskInstance: fetch_spread_values.fetch_and_compute_spread_usd_mxn scheduled__2024-07-14T04:33:00+00:00 [running]> on host 77caf7e4b282
[2024-07-14T20:34:02.042+0000] {taskinstance.py:2648} INFO - Exporting env vars: AIRFLOW_CTX_DAG_OWNER='***' AIRFLOW_CTX_DAG_ID='fetch_spread_values' AIRFLOW_CTX_TASK_ID='fetch_and_compute_spread_usd_mxn' AIRFLOW_CTX_EXECUTION_DATE='2024-07-14T04:33:00+00:00' AIRFLOW_CTX_TRY_NUMBER='1' AIRFLOW_CTX_DAG_RUN_ID='scheduled__2024-07-14T04:33:00+00:00'
[2024-07-14T20:34:02.044+0000] {taskinstance.py:430} INFO - ::endgroup::
[2024-07-14T20:34:02.205+0000] {python.py:237} INFO - Done. Returned value was: None
[2024-07-14T20:34:02.208+0000] {taskinstance.py:441} INFO - ::group::Post task execution logs
[2024-07-14T20:34:02.215+0000] {taskinstance.py:1206} INFO - Marking task as SUCCESS. dag_id=fetch_spread_values, task_id=fetch_and_compute_spread_usd_mxn, run_id=scheduled__2024-07-14T04:33:00+00:00, execution_date=20240714T043300, start_date=20240714T203401, end_date=20240714T203402
[2024-07-14T20:34:02.233+0000] {local_task_job_runner.py:240} INFO - Task exited with return code 0
[2024-07-14T20:34:02.243+0000] {taskinstance.py:3503} INFO - 0 downstream tasks scheduled from follow-on schedule check
[2024-07-14T20:34:02.244+0000] {local_task_job_runner.py:222} INFO - ::endgroup::
[2024-07-15T06:48:53.766+0000] {local_task_job_runner.py:120} INFO - ::group::Pre task execution logs
[2024-07-15T06:48:53.786+0000] {taskinstance.py:2076} INFO - Dependencies all met for dep_context=non-requeueable deps ti=<TaskInstance: fetch_spread_values.fetch_and_compute_spread_usd_mxn scheduled__2024-07-14T04:33:00+00:00 [queued]>
[2024-07-15T06:48:53.794+0000] {taskinstance.py:2076} INFO - Dependencies all met for dep_context=requeueable deps ti=<TaskInstance: fetch_spread_values.fetch_and_compute_spread_usd_mxn scheduled__2024-07-14T04:33:00+00:00 [queued]>
[2024-07-15T06:48:53.794+0000] {taskinstance.py:2306} INFO - Starting attempt 1 of 2
[2024-07-15T06:48:53.824+0000] {taskinstance.py:2330} INFO - Executing <Task(PythonOperator): fetch_and_compute_spread_usd_mxn> on 2024-07-14 04:33:00+00:00
[2024-07-15T06:48:53.828+0000] {logging_mixin.py:188} WARNING - /home/***/.local/lib/python3.12/site-packages/***/task/task_runner/standard_task_runner.py:61 DeprecationWarning: This process (pid=5797) is multi-threaded, use of fork() may lead to deadlocks in the child.
[2024-07-15T06:48:53.833+0000] {standard_task_runner.py:63} INFO - Started process 5808 to run task
[2024-07-15T06:48:53.830+0000] {standard_task_runner.py:90} INFO - Running: ['***', 'tasks', 'run', 'fetch_spread_values', 'fetch_and_compute_spread_usd_mxn', 'scheduled__2024-07-14T04:33:00+00:00', '--job-id', '1468', '--raw', '--subdir', 'DAGS_FOLDER/et_dag.py', '--cfg-path', '/tmp/tmp94jaf6sv']
[2024-07-15T06:48:53.838+0000] {standard_task_runner.py:91} INFO - Job 1468: Subtask fetch_and_compute_spread_usd_mxn
[2024-07-15T06:48:53.885+0000] {task_command.py:426} INFO - Running <TaskInstance: fetch_spread_values.fetch_and_compute_spread_usd_mxn scheduled__2024-07-14T04:33:00+00:00 [running]> on host 52e7a9c3d832
[2024-07-15T06:48:53.977+0000] {taskinstance.py:2648} INFO - Exporting env vars: AIRFLOW_CTX_DAG_OWNER='***' AIRFLOW_CTX_DAG_ID='fetch_spread_values' AIRFLOW_CTX_TASK_ID='fetch_and_compute_spread_usd_mxn' AIRFLOW_CTX_EXECUTION_DATE='2024-07-14T04:33:00+00:00' AIRFLOW_CTX_TRY_NUMBER='1' AIRFLOW_CTX_DAG_RUN_ID='scheduled__2024-07-14T04:33:00+00:00'
[2024-07-15T06:48:53.985+0000] {taskinstance.py:430} INFO - ::endgroup::
[2024-07-15T06:48:54.165+0000] {et_dag.py:27} INFO - Data fetched for book usd_mxn
[2024-07-15T06:48:54.168+0000] {et_dag.py:28} INFO - {'success': True, 'payload': {'high': '18.34', 'last': '18.34', 'created_at': '2024-07-15T06:48:53+00:00', 'book': 'usd_mxn', 'volume': '0', 'vwap': '0', 'low': '18.34', 'ask': '17.61', 'bid': '17.60', 'change_24': '0.00', 'rolling_average_change': {}}}
[2024-07-15T06:48:54.170+0000] {et_dag.py:31} INFO - Spread computed
[2024-07-15T06:48:54.171+0000] {et_dag.py:32} INFO - {'orderbook_timestamp': '2024-07-15T06:48:53+00:00', 'book': 'usd_mxn', 'bid': 17.6, 'ask': 17.61, 'spread': 0.05678591709254975}
[2024-07-15T06:48:54.174+0000] {taskinstance.py:441} INFO - ::group::Post task execution logs
[2024-07-15T06:48:54.175+0000] {taskinstance.py:2905} ERROR - Task failed with exception
Traceback (most recent call last):
  File "/home/airflow/.local/lib/python3.12/site-packages/urllib3/connection.py", line 196, in _new_conn
    sock = connection.create_connection(
           ^^^^^^^^^^^^^^^^^^^^^^^^^^^^^
  File "/home/airflow/.local/lib/python3.12/site-packages/urllib3/util/connection.py", line 85, in create_connection
    raise err
  File "/home/airflow/.local/lib/python3.12/site-packages/urllib3/util/connection.py", line 73, in create_connection
    sock.connect(sa)
ConnectionRefusedError: [Errno 111] Connection refused

The above exception was the direct cause of the following exception:

Traceback (most recent call last):
  File "/home/airflow/.local/lib/python3.12/site-packages/urllib3/connectionpool.py", line 789, in urlopen
    response = self._make_request(
               ^^^^^^^^^^^^^^^^^^^
  File "/home/airflow/.local/lib/python3.12/site-packages/urllib3/connectionpool.py", line 495, in _make_request
    conn.request(
  File "/home/airflow/.local/lib/python3.12/site-packages/urllib3/connection.py", line 398, in request
    self.endheaders()
  File "/usr/local/lib/python3.12/http/client.py", line 1331, in endheaders
    self._send_output(message_body, encode_chunked=encode_chunked)
  File "/usr/local/lib/python3.12/http/client.py", line 1091, in _send_output
    self.send(msg)
  File "/usr/local/lib/python3.12/http/client.py", line 1035, in send
    self.connect()
  File "/home/airflow/.local/lib/python3.12/site-packages/urllib3/connection.py", line 236, in connect
    self.sock = self._new_conn()
                ^^^^^^^^^^^^^^^^
  File "/home/airflow/.local/lib/python3.12/site-packages/urllib3/connection.py", line 211, in _new_conn
    raise NewConnectionError(
urllib3.exceptions.NewConnectionError: <urllib3.connection.HTTPConnection object at 0xffff7bf9f7a0>: Failed to establish a new connection: [Errno 111] Connection refused

The above exception was the direct cause of the following exception:

Traceback (most recent call last):
  File "/home/airflow/.local/lib/python3.12/site-packages/requests/adapters.py", line 486, in send
    resp = conn.urlopen(
           ^^^^^^^^^^^^^
  File "/home/airflow/.local/lib/python3.12/site-packages/urllib3/connectionpool.py", line 843, in urlopen
    retries = retries.increment(
              ^^^^^^^^^^^^^^^^^^
  File "/home/airflow/.local/lib/python3.12/site-packages/urllib3/util/retry.py", line 519, in increment
    raise MaxRetryError(_pool, url, reason) from reason  # type: ignore[arg-type]
    ^^^^^^^^^^^^^^^^^^^^^^^^^^^^^^^^^^^^^^^^^^^^^^^^^^^
urllib3.exceptions.MaxRetryError: HTTPConnectionPool(host='127.0.0.1', port=8000): Max retries exceeded with url: /store_spread (Caused by NewConnectionError('<urllib3.connection.HTTPConnection object at 0xffff7bf9f7a0>: Failed to establish a new connection: [Errno 111] Connection refused'))

During handling of the above exception, another exception occurred:

Traceback (most recent call last):
  File "/home/airflow/.local/lib/python3.12/site-packages/airflow/models/taskinstance.py", line 465, in _execute_task
    result = _execute_callable(context=context, **execute_callable_kwargs)
             ^^^^^^^^^^^^^^^^^^^^^^^^^^^^^^^^^^^^^^^^^^^^^^^^^^^^^^^^^^^^^
  File "/home/airflow/.local/lib/python3.12/site-packages/airflow/models/taskinstance.py", line 432, in _execute_callable
    return execute_callable(context=context, **execute_callable_kwargs)
           ^^^^^^^^^^^^^^^^^^^^^^^^^^^^^^^^^^^^^^^^^^^^^^^^^^^^^^^^^^^^
  File "/home/airflow/.local/lib/python3.12/site-packages/airflow/models/baseoperator.py", line 401, in wrapper
    return func(self, *args, **kwargs)
           ^^^^^^^^^^^^^^^^^^^^^^^^^^^
  File "/home/airflow/.local/lib/python3.12/site-packages/airflow/operators/python.py", line 235, in execute
    return_value = self.execute_callable()
                   ^^^^^^^^^^^^^^^^^^^^^^^
  File "/home/airflow/.local/lib/python3.12/site-packages/airflow/operators/python.py", line 252, in execute_callable
    return self.python_callable(*self.op_args, **self.op_kwargs)
           ^^^^^^^^^^^^^^^^^^^^^^^^^^^^^^^^^^^^^^^^^^^^^^^^^^^^^
  File "/opt/airflow/dags/et_dag.py", line 34, in trigger_fetch_and_compute
    response = requests.post(URL_STORE_RECORD, headers=HEADERS_JSON, json=spread_record)
               ^^^^^^^^^^^^^^^^^^^^^^^^^^^^^^^^^^^^^^^^^^^^^^^^^^^^^^^^^^^^^^^^^^^^^^^^^
  File "/home/airflow/.local/lib/python3.12/site-packages/requests/api.py", line 115, in post
    return request("post", url, data=data, json=json, **kwargs)
           ^^^^^^^^^^^^^^^^^^^^^^^^^^^^^^^^^^^^^^^^^^^^^^^^^^^^
  File "/home/airflow/.local/lib/python3.12/site-packages/requests/api.py", line 59, in request
    return session.request(method=method, url=url, **kwargs)
           ^^^^^^^^^^^^^^^^^^^^^^^^^^^^^^^^^^^^^^^^^^^^^^^^^
  File "/home/airflow/.local/lib/python3.12/site-packages/requests/sessions.py", line 589, in request
    resp = self.send(prep, **send_kwargs)
           ^^^^^^^^^^^^^^^^^^^^^^^^^^^^^^
  File "/home/airflow/.local/lib/python3.12/site-packages/requests/sessions.py", line 703, in send
    r = adapter.send(request, **kwargs)
        ^^^^^^^^^^^^^^^^^^^^^^^^^^^^^^^
  File "/home/airflow/.local/lib/python3.12/site-packages/requests/adapters.py", line 519, in send
    raise ConnectionError(e, request=request)
requests.exceptions.ConnectionError: HTTPConnectionPool(host='127.0.0.1', port=8000): Max retries exceeded with url: /store_spread (Caused by NewConnectionError('<urllib3.connection.HTTPConnection object at 0xffff7bf9f7a0>: Failed to establish a new connection: [Errno 111] Connection refused'))
[2024-07-15T06:48:54.198+0000] {taskinstance.py:1206} INFO - Marking task as UP_FOR_RETRY. dag_id=fetch_spread_values, task_id=fetch_and_compute_spread_usd_mxn, run_id=scheduled__2024-07-14T04:33:00+00:00, execution_date=20240714T043300, start_date=20240715T064853, end_date=20240715T064854
[2024-07-15T06:48:54.241+0000] {standard_task_runner.py:110} ERROR - Failed to execute job 1468 for task fetch_and_compute_spread_usd_mxn (HTTPConnectionPool(host='127.0.0.1', port=8000): Max retries exceeded with url: /store_spread (Caused by NewConnectionError('<urllib3.connection.HTTPConnection object at 0xffff7bf9f7a0>: Failed to establish a new connection: [Errno 111] Connection refused')); 5808)
[2024-07-15T06:48:54.289+0000] {local_task_job_runner.py:240} INFO - Task exited with return code 1
[2024-07-15T06:48:54.312+0000] {local_task_job_runner.py:222} INFO - ::endgroup::
