[2024-07-14T09:00:27.485+0000] {local_task_job_runner.py:120} INFO - ::group::Pre task execution logs
[2024-07-14T09:00:27.525+0000] {taskinstance.py:2076} INFO - Dependencies all met for dep_context=non-requeueable deps ti=<TaskInstance: fetch_spread_values.fetch_and_compute_spread_btc_mxn scheduled__2024-07-14T03:52:00+00:00 [queued]>
[2024-07-14T09:00:27.548+0000] {taskinstance.py:2076} INFO - Dependencies all met for dep_context=requeueable deps ti=<TaskInstance: fetch_spread_values.fetch_and_compute_spread_btc_mxn scheduled__2024-07-14T03:52:00+00:00 [queued]>
[2024-07-14T09:00:27.550+0000] {taskinstance.py:2306} INFO - Starting attempt 1 of 2
[2024-07-14T09:00:27.576+0000] {taskinstance.py:2330} INFO - Executing <Task(PythonOperator): fetch_and_compute_spread_btc_mxn> on 2024-07-14 03:52:00+00:00
[2024-07-14T09:00:27.618+0000] {warnings.py:112} WARNING - /home/***/.local/lib/python3.12/site-packages/***/task/task_runner/standard_task_runner.py:61: DeprecationWarning: This process (pid=1541) is multi-threaded, use of fork() may lead to deadlocks in the child.
  pid = os.fork()

[2024-07-14T09:00:27.625+0000] {standard_task_runner.py:63} INFO - Started process 1563 to run task
[2024-07-14T09:00:27.616+0000] {standard_task_runner.py:90} INFO - Running: ['***', 'tasks', 'run', 'fetch_spread_values', 'fetch_and_compute_spread_btc_mxn', 'scheduled__2024-07-14T03:52:00+00:00', '--job-id', '492', '--raw', '--subdir', 'DAGS_FOLDER/***.py', '--cfg-path', '/tmp/tmp22f7ugni']
[2024-07-14T09:00:27.636+0000] {standard_task_runner.py:91} INFO - Job 492: Subtask fetch_and_compute_spread_btc_mxn
[2024-07-14T09:00:27.705+0000] {task_command.py:426} INFO - Running <TaskInstance: fetch_spread_values.fetch_and_compute_spread_btc_mxn scheduled__2024-07-14T03:52:00+00:00 [running]> on host d537c34a4880
[2024-07-14T09:00:27.836+0000] {taskinstance.py:2648} INFO - Exporting env vars: AIRFLOW_CTX_DAG_OWNER='***' AIRFLOW_CTX_DAG_ID='fetch_spread_values' AIRFLOW_CTX_TASK_ID='fetch_and_compute_spread_btc_mxn' AIRFLOW_CTX_EXECUTION_DATE='2024-07-14T03:52:00+00:00' AIRFLOW_CTX_TRY_NUMBER='1' AIRFLOW_CTX_DAG_RUN_ID='scheduled__2024-07-14T03:52:00+00:00'
[2024-07-14T09:00:27.851+0000] {taskinstance.py:430} INFO - ::endgroup::
[2024-07-14T09:00:28.033+0000] {python.py:237} INFO - Done. Returned value was: None
[2024-07-14T09:00:28.035+0000] {taskinstance.py:441} INFO - ::group::Post task execution logs
[2024-07-14T09:00:28.042+0000] {taskinstance.py:1206} INFO - Marking task as SUCCESS. dag_id=fetch_spread_values, task_id=fetch_and_compute_spread_btc_mxn, run_id=scheduled__2024-07-14T03:52:00+00:00, execution_date=20240714T035200, start_date=20240714T090027, end_date=20240714T090028
[2024-07-14T09:00:28.075+0000] {local_task_job_runner.py:240} INFO - Task exited with return code 0
[2024-07-14T09:00:28.086+0000] {taskinstance.py:3503} INFO - 0 downstream tasks scheduled from follow-on schedule check
[2024-07-14T09:00:28.088+0000] {local_task_job_runner.py:222} INFO - ::endgroup::
[2024-07-14T20:33:46.446+0000] {local_task_job_runner.py:120} INFO - ::group::Pre task execution logs
[2024-07-14T20:33:46.489+0000] {taskinstance.py:2076} INFO - Dependencies all met for dep_context=non-requeueable deps ti=<TaskInstance: fetch_spread_values.fetch_and_compute_spread_btc_mxn scheduled__2024-07-14T03:52:00+00:00 [queued]>
[2024-07-14T20:33:46.502+0000] {taskinstance.py:2076} INFO - Dependencies all met for dep_context=requeueable deps ti=<TaskInstance: fetch_spread_values.fetch_and_compute_spread_btc_mxn scheduled__2024-07-14T03:52:00+00:00 [queued]>
[2024-07-14T20:33:46.505+0000] {taskinstance.py:2306} INFO - Starting attempt 1 of 2
[2024-07-14T20:33:46.532+0000] {taskinstance.py:2330} INFO - Executing <Task(PythonOperator): fetch_and_compute_spread_btc_mxn> on 2024-07-14 03:52:00+00:00
[2024-07-14T20:33:46.538+0000] {logging_mixin.py:188} WARNING - /home/***/.local/lib/python3.12/site-packages/***/task/task_runner/standard_task_runner.py:61 DeprecationWarning: This process (pid=1128) is multi-threaded, use of fork() may lead to deadlocks in the child.
[2024-07-14T20:33:46.539+0000] {standard_task_runner.py:90} INFO - Running: ['***', 'tasks', 'run', 'fetch_spread_values', 'fetch_and_compute_spread_btc_mxn', 'scheduled__2024-07-14T03:52:00+00:00', '--job-id', '469', '--raw', '--subdir', 'DAGS_FOLDER/***.py', '--cfg-path', '/tmp/tmp2k_9szpb']
[2024-07-14T20:33:46.542+0000] {standard_task_runner.py:91} INFO - Job 469: Subtask fetch_and_compute_spread_btc_mxn
[2024-07-14T20:33:46.541+0000] {standard_task_runner.py:63} INFO - Started process 1134 to run task
[2024-07-14T20:33:46.589+0000] {task_command.py:426} INFO - Running <TaskInstance: fetch_spread_values.fetch_and_compute_spread_btc_mxn scheduled__2024-07-14T03:52:00+00:00 [running]> on host 77caf7e4b282
[2024-07-14T20:33:46.640+0000] {taskinstance.py:2648} INFO - Exporting env vars: AIRFLOW_CTX_DAG_OWNER='***' AIRFLOW_CTX_DAG_ID='fetch_spread_values' AIRFLOW_CTX_TASK_ID='fetch_and_compute_spread_btc_mxn' AIRFLOW_CTX_EXECUTION_DATE='2024-07-14T03:52:00+00:00' AIRFLOW_CTX_TRY_NUMBER='1' AIRFLOW_CTX_DAG_RUN_ID='scheduled__2024-07-14T03:52:00+00:00'
[2024-07-14T20:33:46.641+0000] {taskinstance.py:430} INFO - ::endgroup::
[2024-07-14T20:33:46.816+0000] {python.py:237} INFO - Done. Returned value was: None
[2024-07-14T20:33:46.817+0000] {taskinstance.py:441} INFO - ::group::Post task execution logs
[2024-07-14T20:33:46.824+0000] {taskinstance.py:1206} INFO - Marking task as SUCCESS. dag_id=fetch_spread_values, task_id=fetch_and_compute_spread_btc_mxn, run_id=scheduled__2024-07-14T03:52:00+00:00, execution_date=20240714T035200, start_date=20240714T203346, end_date=20240714T203346
[2024-07-14T20:33:46.856+0000] {local_task_job_runner.py:240} INFO - Task exited with return code 0
[2024-07-14T20:33:46.865+0000] {taskinstance.py:3503} INFO - 0 downstream tasks scheduled from follow-on schedule check
[2024-07-14T20:33:46.866+0000] {local_task_job_runner.py:222} INFO - ::endgroup::
[2024-07-15T06:45:34.574+0000] {local_task_job_runner.py:120} INFO - ::group::Pre task execution logs
[2024-07-15T06:45:34.591+0000] {taskinstance.py:2076} INFO - Dependencies all met for dep_context=non-requeueable deps ti=<TaskInstance: fetch_spread_values.fetch_and_compute_spread_btc_mxn scheduled__2024-07-14T03:52:00+00:00 [queued]>
[2024-07-15T06:45:34.595+0000] {taskinstance.py:2076} INFO - Dependencies all met for dep_context=requeueable deps ti=<TaskInstance: fetch_spread_values.fetch_and_compute_spread_btc_mxn scheduled__2024-07-14T03:52:00+00:00 [queued]>
[2024-07-15T06:45:34.596+0000] {taskinstance.py:2306} INFO - Starting attempt 1 of 2
[2024-07-15T06:45:34.640+0000] {taskinstance.py:2330} INFO - Executing <Task(PythonOperator): fetch_and_compute_spread_btc_mxn> on 2024-07-14 03:52:00+00:00
[2024-07-15T06:45:34.644+0000] {logging_mixin.py:188} WARNING - /home/***/.local/lib/python3.12/site-packages/***/task/task_runner/standard_task_runner.py:61 DeprecationWarning: This process (pid=5378) is multi-threaded, use of fork() may lead to deadlocks in the child.
[2024-07-15T06:45:34.646+0000] {standard_task_runner.py:63} INFO - Started process 5384 to run task
[2024-07-15T06:45:34.645+0000] {standard_task_runner.py:90} INFO - Running: ['***', 'tasks', 'run', 'fetch_spread_values', 'fetch_and_compute_spread_btc_mxn', 'scheduled__2024-07-14T03:52:00+00:00', '--job-id', '1293', '--raw', '--subdir', 'DAGS_FOLDER/et_dag.py', '--cfg-path', '/tmp/tmpnxqf9ppg']
[2024-07-15T06:45:34.647+0000] {standard_task_runner.py:91} INFO - Job 1293: Subtask fetch_and_compute_spread_btc_mxn
[2024-07-15T06:45:34.688+0000] {task_command.py:426} INFO - Running <TaskInstance: fetch_spread_values.fetch_and_compute_spread_btc_mxn scheduled__2024-07-14T03:52:00+00:00 [running]> on host 52e7a9c3d832
[2024-07-15T06:45:34.745+0000] {taskinstance.py:2648} INFO - Exporting env vars: AIRFLOW_CTX_DAG_OWNER='***' AIRFLOW_CTX_DAG_ID='fetch_spread_values' AIRFLOW_CTX_TASK_ID='fetch_and_compute_spread_btc_mxn' AIRFLOW_CTX_EXECUTION_DATE='2024-07-14T03:52:00+00:00' AIRFLOW_CTX_TRY_NUMBER='1' AIRFLOW_CTX_DAG_RUN_ID='scheduled__2024-07-14T03:52:00+00:00'
[2024-07-15T06:45:34.748+0000] {taskinstance.py:430} INFO - ::endgroup::
[2024-07-15T06:45:34.927+0000] {et_dag.py:27} INFO - Data fetched for book btc_mxn
[2024-07-15T06:45:34.933+0000] {et_dag.py:28} INFO - {'success': True, 'payload': {'high': '1119480.00', 'last': '1119480.00', 'created_at': '2024-07-15T06:45:34+00:00', 'book': 'btc_mxn', 'volume': '0', 'vwap': '0', 'low': '1119480.00', 'ask': '1023070.02', 'bid': '1023069.98', 'change_24': '0.00', 'rolling_average_change': {}}}
[2024-07-15T06:45:34.934+0000] {et_dag.py:31} INFO - Spread computed
[2024-07-15T06:45:34.935+0000] {et_dag.py:32} INFO - {'orderbook_timestamp': '2024-07-15T06:45:34+00:00', 'book': 'btc_mxn', 'bid': 1023069.98, 'ask': 1023070.02, 'spread': 3.909800820598076e-06}
[2024-07-15T06:45:34.937+0000] {taskinstance.py:441} INFO - ::group::Post task execution logs
[2024-07-15T06:45:34.938+0000] {taskinstance.py:2905} ERROR - Task failed with exception
Traceback (most recent call last):
  File "/home/airflow/.local/lib/python3.12/site-packages/urllib3/connection.py", line 196, in _new_conn
    sock = connection.create_connection(
           ^^^^^^^^^^^^^^^^^^^^^^^^^^^^^
  File "/home/airflow/.local/lib/python3.12/site-packages/urllib3/util/connection.py", line 85, in create_connection
    raise err
  File "/home/airflow/.local/lib/python3.12/site-packages/urllib3/util/connection.py", line 73, in create_connection
    sock.connect(sa)
ConnectionRefusedError: [Errno 111] Connection refused

The above exception was the direct cause of the following exception:

Traceback (most recent call last):
  File "/home/airflow/.local/lib/python3.12/site-packages/urllib3/connectionpool.py", line 789, in urlopen
    response = self._make_request(
               ^^^^^^^^^^^^^^^^^^^
  File "/home/airflow/.local/lib/python3.12/site-packages/urllib3/connectionpool.py", line 495, in _make_request
    conn.request(
  File "/home/airflow/.local/lib/python3.12/site-packages/urllib3/connection.py", line 398, in request
    self.endheaders()
  File "/usr/local/lib/python3.12/http/client.py", line 1331, in endheaders
    self._send_output(message_body, encode_chunked=encode_chunked)
  File "/usr/local/lib/python3.12/http/client.py", line 1091, in _send_output
    self.send(msg)
  File "/usr/local/lib/python3.12/http/client.py", line 1035, in send
    self.connect()
  File "/home/airflow/.local/lib/python3.12/site-packages/urllib3/connection.py", line 236, in connect
    self.sock = self._new_conn()
                ^^^^^^^^^^^^^^^^
  File "/home/airflow/.local/lib/python3.12/site-packages/urllib3/connection.py", line 211, in _new_conn
    raise NewConnectionError(
urllib3.exceptions.NewConnectionError: <urllib3.connection.HTTPConnection object at 0xffff7bf9f7a0>: Failed to establish a new connection: [Errno 111] Connection refused

The above exception was the direct cause of the following exception:

Traceback (most recent call last):
  File "/home/airflow/.local/lib/python3.12/site-packages/requests/adapters.py", line 486, in send
    resp = conn.urlopen(
           ^^^^^^^^^^^^^
  File "/home/airflow/.local/lib/python3.12/site-packages/urllib3/connectionpool.py", line 843, in urlopen
    retries = retries.increment(
              ^^^^^^^^^^^^^^^^^^
  File "/home/airflow/.local/lib/python3.12/site-packages/urllib3/util/retry.py", line 519, in increment
    raise MaxRetryError(_pool, url, reason) from reason  # type: ignore[arg-type]
    ^^^^^^^^^^^^^^^^^^^^^^^^^^^^^^^^^^^^^^^^^^^^^^^^^^^
urllib3.exceptions.MaxRetryError: HTTPConnectionPool(host='127.0.0.1', port=8000): Max retries exceeded with url: /store_spread (Caused by NewConnectionError('<urllib3.connection.HTTPConnection object at 0xffff7bf9f7a0>: Failed to establish a new connection: [Errno 111] Connection refused'))

During handling of the above exception, another exception occurred:

Traceback (most recent call last):
  File "/home/airflow/.local/lib/python3.12/site-packages/airflow/models/taskinstance.py", line 465, in _execute_task
    result = _execute_callable(context=context, **execute_callable_kwargs)
             ^^^^^^^^^^^^^^^^^^^^^^^^^^^^^^^^^^^^^^^^^^^^^^^^^^^^^^^^^^^^^
  File "/home/airflow/.local/lib/python3.12/site-packages/airflow/models/taskinstance.py", line 432, in _execute_callable
    return execute_callable(context=context, **execute_callable_kwargs)
           ^^^^^^^^^^^^^^^^^^^^^^^^^^^^^^^^^^^^^^^^^^^^^^^^^^^^^^^^^^^^
  File "/home/airflow/.local/lib/python3.12/site-packages/airflow/models/baseoperator.py", line 401, in wrapper
    return func(self, *args, **kwargs)
           ^^^^^^^^^^^^^^^^^^^^^^^^^^^
  File "/home/airflow/.local/lib/python3.12/site-packages/airflow/operators/python.py", line 235, in execute
    return_value = self.execute_callable()
                   ^^^^^^^^^^^^^^^^^^^^^^^
  File "/home/airflow/.local/lib/python3.12/site-packages/airflow/operators/python.py", line 252, in execute_callable
    return self.python_callable(*self.op_args, **self.op_kwargs)
           ^^^^^^^^^^^^^^^^^^^^^^^^^^^^^^^^^^^^^^^^^^^^^^^^^^^^^
  File "/opt/airflow/dags/et_dag.py", line 34, in trigger_fetch_and_compute
    response = requests.post(URL_STORE_RECORD, headers=HEADERS_JSON, json=spread_record)
               ^^^^^^^^^^^^^^^^^^^^^^^^^^^^^^^^^^^^^^^^^^^^^^^^^^^^^^^^^^^^^^^^^^^^^^^^^
  File "/home/airflow/.local/lib/python3.12/site-packages/requests/api.py", line 115, in post
    return request("post", url, data=data, json=json, **kwargs)
           ^^^^^^^^^^^^^^^^^^^^^^^^^^^^^^^^^^^^^^^^^^^^^^^^^^^^
  File "/home/airflow/.local/lib/python3.12/site-packages/requests/api.py", line 59, in request
    return session.request(method=method, url=url, **kwargs)
           ^^^^^^^^^^^^^^^^^^^^^^^^^^^^^^^^^^^^^^^^^^^^^^^^^
  File "/home/airflow/.local/lib/python3.12/site-packages/requests/sessions.py", line 589, in request
    resp = self.send(prep, **send_kwargs)
           ^^^^^^^^^^^^^^^^^^^^^^^^^^^^^^
  File "/home/airflow/.local/lib/python3.12/site-packages/requests/sessions.py", line 703, in send
    r = adapter.send(request, **kwargs)
        ^^^^^^^^^^^^^^^^^^^^^^^^^^^^^^^
  File "/home/airflow/.local/lib/python3.12/site-packages/requests/adapters.py", line 519, in send
    raise ConnectionError(e, request=request)
requests.exceptions.ConnectionError: HTTPConnectionPool(host='127.0.0.1', port=8000): Max retries exceeded with url: /store_spread (Caused by NewConnectionError('<urllib3.connection.HTTPConnection object at 0xffff7bf9f7a0>: Failed to establish a new connection: [Errno 111] Connection refused'))
[2024-07-15T06:45:34.960+0000] {taskinstance.py:1206} INFO - Marking task as UP_FOR_RETRY. dag_id=fetch_spread_values, task_id=fetch_and_compute_spread_btc_mxn, run_id=scheduled__2024-07-14T03:52:00+00:00, execution_date=20240714T035200, start_date=20240715T064534, end_date=20240715T064534
[2024-07-15T06:45:34.990+0000] {standard_task_runner.py:110} ERROR - Failed to execute job 1293 for task fetch_and_compute_spread_btc_mxn (HTTPConnectionPool(host='127.0.0.1', port=8000): Max retries exceeded with url: /store_spread (Caused by NewConnectionError('<urllib3.connection.HTTPConnection object at 0xffff7bf9f7a0>: Failed to establish a new connection: [Errno 111] Connection refused')); 5384)
[2024-07-15T06:45:35.038+0000] {local_task_job_runner.py:240} INFO - Task exited with return code 1
[2024-07-15T06:45:35.047+0000] {local_task_job_runner.py:222} INFO - ::endgroup::
