[2024-07-15T06:41:12.804+0000] {local_task_job_runner.py:120} INFO - ::group::Pre task execution logs
[2024-07-15T06:41:12.843+0000] {taskinstance.py:2076} INFO - Dependencies all met for dep_context=non-requeueable deps ti=<TaskInstance: save_spread_values.save_and_flush_task scheduled__2024-07-15T03:30:00+00:00 [queued]>
[2024-07-15T06:41:12.854+0000] {taskinstance.py:2076} INFO - Dependencies all met for dep_context=requeueable deps ti=<TaskInstance: save_spread_values.save_and_flush_task scheduled__2024-07-15T03:30:00+00:00 [queued]>
[2024-07-15T06:41:12.855+0000] {taskinstance.py:2306} INFO - Starting attempt 1 of 2
[2024-07-15T06:41:12.937+0000] {taskinstance.py:2330} INFO - Executing <Task(PythonOperator): save_and_flush_task> on 2024-07-15 03:30:00+00:00
[2024-07-15T06:41:12.943+0000] {logging_mixin.py:188} WARNING - /home/***/.local/lib/python3.12/site-packages/***/task/task_runner/standard_task_runner.py:61 DeprecationWarning: This process (pid=4679) is multi-threaded, use of fork() may lead to deadlocks in the child.
[2024-07-15T06:41:12.946+0000] {standard_task_runner.py:63} INFO - Started process 4691 to run task
[2024-07-15T06:41:12.943+0000] {standard_task_runner.py:90} INFO - Running: ['***', 'tasks', 'run', 'save_spread_values', 'save_and_flush_task', 'scheduled__2024-07-15T03:30:00+00:00', '--job-id', '987', '--raw', '--subdir', 'DAGS_FOLDER/et_dag.py', '--cfg-path', '/tmp/tmpxtfx933z']
[2024-07-15T06:41:12.949+0000] {standard_task_runner.py:91} INFO - Job 987: Subtask save_and_flush_task
[2024-07-15T06:41:13.014+0000] {task_command.py:426} INFO - Running <TaskInstance: save_spread_values.save_and_flush_task scheduled__2024-07-15T03:30:00+00:00 [running]> on host 52e7a9c3d832
[2024-07-15T06:41:13.090+0000] {taskinstance.py:2648} INFO - Exporting env vars: AIRFLOW_CTX_DAG_OWNER='***' AIRFLOW_CTX_DAG_ID='save_spread_values' AIRFLOW_CTX_TASK_ID='save_and_flush_task' AIRFLOW_CTX_EXECUTION_DATE='2024-07-15T03:30:00+00:00' AIRFLOW_CTX_TRY_NUMBER='1' AIRFLOW_CTX_DAG_RUN_ID='scheduled__2024-07-15T03:30:00+00:00'
[2024-07-15T06:41:13.092+0000] {taskinstance.py:430} INFO - ::endgroup::
[2024-07-15T06:41:13.103+0000] {taskinstance.py:441} INFO - ::group::Post task execution logs
[2024-07-15T06:41:13.104+0000] {taskinstance.py:2905} ERROR - Task failed with exception
Traceback (most recent call last):
  File "/home/airflow/.local/lib/python3.12/site-packages/airflow/models/taskinstance.py", line 465, in _execute_task
    result = _execute_callable(context=context, **execute_callable_kwargs)
             ^^^^^^^^^^^^^^^^^^^^^^^^^^^^^^^^^^^^^^^^^^^^^^^^^^^^^^^^^^^^^
  File "/home/airflow/.local/lib/python3.12/site-packages/airflow/models/taskinstance.py", line 432, in _execute_callable
    return execute_callable(context=context, **execute_callable_kwargs)
           ^^^^^^^^^^^^^^^^^^^^^^^^^^^^^^^^^^^^^^^^^^^^^^^^^^^^^^^^^^^^
  File "/home/airflow/.local/lib/python3.12/site-packages/airflow/models/baseoperator.py", line 401, in wrapper
    return func(self, *args, **kwargs)
           ^^^^^^^^^^^^^^^^^^^^^^^^^^^
  File "/home/airflow/.local/lib/python3.12/site-packages/airflow/operators/python.py", line 235, in execute
    return_value = self.execute_callable()
                   ^^^^^^^^^^^^^^^^^^^^^^^
  File "/home/airflow/.local/lib/python3.12/site-packages/airflow/operators/python.py", line 252, in execute_callable
    return self.python_callable(*self.op_args, **self.op_kwargs)
           ^^^^^^^^^^^^^^^^^^^^^^^^^^^^^^^^^^^^^^^^^^^^^^^^^^^^^
  File "/opt/airflow/dags/et_dag.py", line 38, in trigger_save_and_flush
    logging('Invoking method to save data from records')
TypeError: 'module' object is not callable
[2024-07-15T06:41:13.113+0000] {taskinstance.py:1206} INFO - Marking task as UP_FOR_RETRY. dag_id=save_spread_values, task_id=save_and_flush_task, run_id=scheduled__2024-07-15T03:30:00+00:00, execution_date=20240715T033000, start_date=20240715T064112, end_date=20240715T064113
[2024-07-15T06:41:13.121+0000] {standard_task_runner.py:110} ERROR - Failed to execute job 987 for task save_and_flush_task ('module' object is not callable; 4691)
[2024-07-15T06:41:13.136+0000] {local_task_job_runner.py:240} INFO - Task exited with return code 1
[2024-07-15T06:41:13.154+0000] {taskinstance.py:3503} INFO - 0 downstream tasks scheduled from follow-on schedule check
[2024-07-15T06:41:13.156+0000] {local_task_job_runner.py:222} INFO - ::endgroup::
