[2024-07-14T08:59:04.711+0000] {local_task_job_runner.py:120} INFO - ::group::Pre task execution logs
[2024-07-14T08:59:04.726+0000] {taskinstance.py:2076} INFO - Dependencies all met for dep_context=non-requeueable deps ti=<TaskInstance: fetch_spread_values.fetch_and_compute_spread_btc_mxn scheduled__2024-07-14T02:33:00+00:00 [queued]>
[2024-07-14T08:59:04.734+0000] {taskinstance.py:2076} INFO - Dependencies all met for dep_context=requeueable deps ti=<TaskInstance: fetch_spread_values.fetch_and_compute_spread_btc_mxn scheduled__2024-07-14T02:33:00+00:00 [queued]>
[2024-07-14T08:59:04.735+0000] {taskinstance.py:2306} INFO - Starting attempt 1 of 2
[2024-07-14T08:59:04.746+0000] {taskinstance.py:2330} INFO - Executing <Task(PythonOperator): fetch_and_compute_spread_btc_mxn> on 2024-07-14 02:33:00+00:00
[2024-07-14T08:59:04.751+0000] {warnings.py:112} WARNING - /home/***/.local/lib/python3.12/site-packages/***/task/task_runner/standard_task_runner.py:61: DeprecationWarning: This process (pid=1061) is multi-threaded, use of fork() may lead to deadlocks in the child.
  pid = os.fork()

[2024-07-14T08:59:04.754+0000] {standard_task_runner.py:63} INFO - Started process 1076 to run task
[2024-07-14T08:59:04.753+0000] {standard_task_runner.py:90} INFO - Running: ['***', 'tasks', 'run', 'fetch_spread_values', 'fetch_and_compute_spread_btc_mxn', 'scheduled__2024-07-14T02:33:00+00:00', '--job-id', '337', '--raw', '--subdir', 'DAGS_FOLDER/***.py', '--cfg-path', '/tmp/tmpfaeis6ep']
[2024-07-14T08:59:04.756+0000] {standard_task_runner.py:91} INFO - Job 337: Subtask fetch_and_compute_spread_btc_mxn
[2024-07-14T08:59:04.801+0000] {task_command.py:426} INFO - Running <TaskInstance: fetch_spread_values.fetch_and_compute_spread_btc_mxn scheduled__2024-07-14T02:33:00+00:00 [running]> on host d537c34a4880
[2024-07-14T08:59:04.893+0000] {taskinstance.py:2648} INFO - Exporting env vars: AIRFLOW_CTX_DAG_OWNER='***' AIRFLOW_CTX_DAG_ID='fetch_spread_values' AIRFLOW_CTX_TASK_ID='fetch_and_compute_spread_btc_mxn' AIRFLOW_CTX_EXECUTION_DATE='2024-07-14T02:33:00+00:00' AIRFLOW_CTX_TRY_NUMBER='1' AIRFLOW_CTX_DAG_RUN_ID='scheduled__2024-07-14T02:33:00+00:00'
[2024-07-14T08:59:04.895+0000] {taskinstance.py:430} INFO - ::endgroup::
[2024-07-14T08:59:05.037+0000] {python.py:237} INFO - Done. Returned value was: None
[2024-07-14T08:59:05.040+0000] {taskinstance.py:441} INFO - ::group::Post task execution logs
[2024-07-14T08:59:05.048+0000] {taskinstance.py:1206} INFO - Marking task as SUCCESS. dag_id=fetch_spread_values, task_id=fetch_and_compute_spread_btc_mxn, run_id=scheduled__2024-07-14T02:33:00+00:00, execution_date=20240714T023300, start_date=20240714T085904, end_date=20240714T085905
[2024-07-14T08:59:05.068+0000] {local_task_job_runner.py:240} INFO - Task exited with return code 0
[2024-07-14T08:59:05.091+0000] {taskinstance.py:3503} INFO - 0 downstream tasks scheduled from follow-on schedule check
[2024-07-14T08:59:05.093+0000] {local_task_job_runner.py:222} INFO - ::endgroup::
[2024-07-14T20:33:21.042+0000] {local_task_job_runner.py:120} INFO - ::group::Pre task execution logs
[2024-07-14T20:33:21.063+0000] {taskinstance.py:2076} INFO - Dependencies all met for dep_context=non-requeueable deps ti=<TaskInstance: fetch_spread_values.fetch_and_compute_spread_btc_mxn scheduled__2024-07-14T02:33:00+00:00 [queued]>
[2024-07-14T20:33:21.068+0000] {taskinstance.py:2076} INFO - Dependencies all met for dep_context=requeueable deps ti=<TaskInstance: fetch_spread_values.fetch_and_compute_spread_btc_mxn scheduled__2024-07-14T02:33:00+00:00 [queued]>
[2024-07-14T20:33:21.070+0000] {taskinstance.py:2306} INFO - Starting attempt 1 of 2
[2024-07-14T20:33:21.094+0000] {taskinstance.py:2330} INFO - Executing <Task(PythonOperator): fetch_and_compute_spread_btc_mxn> on 2024-07-14 02:33:00+00:00
[2024-07-14T20:33:21.099+0000] {logging_mixin.py:188} WARNING - /home/***/.local/lib/python3.12/site-packages/***/task/task_runner/standard_task_runner.py:61 DeprecationWarning: This process (pid=811) is multi-threaded, use of fork() may lead to deadlocks in the child.
[2024-07-14T20:33:21.101+0000] {standard_task_runner.py:63} INFO - Started process 820 to run task
[2024-07-14T20:33:21.102+0000] {standard_task_runner.py:90} INFO - Running: ['***', 'tasks', 'run', 'fetch_spread_values', 'fetch_and_compute_spread_btc_mxn', 'scheduled__2024-07-14T02:33:00+00:00', '--job-id', '312', '--raw', '--subdir', 'DAGS_FOLDER/***.py', '--cfg-path', '/tmp/tmp9s77xavq']
[2024-07-14T20:33:21.109+0000] {standard_task_runner.py:91} INFO - Job 312: Subtask fetch_and_compute_spread_btc_mxn
[2024-07-14T20:33:21.177+0000] {task_command.py:426} INFO - Running <TaskInstance: fetch_spread_values.fetch_and_compute_spread_btc_mxn scheduled__2024-07-14T02:33:00+00:00 [running]> on host 77caf7e4b282
[2024-07-14T20:33:21.269+0000] {taskinstance.py:2648} INFO - Exporting env vars: AIRFLOW_CTX_DAG_OWNER='***' AIRFLOW_CTX_DAG_ID='fetch_spread_values' AIRFLOW_CTX_TASK_ID='fetch_and_compute_spread_btc_mxn' AIRFLOW_CTX_EXECUTION_DATE='2024-07-14T02:33:00+00:00' AIRFLOW_CTX_TRY_NUMBER='1' AIRFLOW_CTX_DAG_RUN_ID='scheduled__2024-07-14T02:33:00+00:00'
[2024-07-14T20:33:21.271+0000] {taskinstance.py:430} INFO - ::endgroup::
[2024-07-14T20:33:21.457+0000] {python.py:237} INFO - Done. Returned value was: None
[2024-07-14T20:33:21.460+0000] {taskinstance.py:441} INFO - ::group::Post task execution logs
[2024-07-14T20:33:21.465+0000] {taskinstance.py:1206} INFO - Marking task as SUCCESS. dag_id=fetch_spread_values, task_id=fetch_and_compute_spread_btc_mxn, run_id=scheduled__2024-07-14T02:33:00+00:00, execution_date=20240714T023300, start_date=20240714T203321, end_date=20240714T203321
[2024-07-14T20:33:21.493+0000] {local_task_job_runner.py:240} INFO - Task exited with return code 0
[2024-07-14T20:33:21.502+0000] {taskinstance.py:3503} INFO - 0 downstream tasks scheduled from follow-on schedule check
[2024-07-14T20:33:21.503+0000] {local_task_job_runner.py:222} INFO - ::endgroup::
[2024-07-15T06:40:07.909+0000] {local_task_job_runner.py:120} INFO - ::group::Pre task execution logs
[2024-07-15T06:40:07.936+0000] {taskinstance.py:2076} INFO - Dependencies all met for dep_context=non-requeueable deps ti=<TaskInstance: fetch_spread_values.fetch_and_compute_spread_btc_mxn scheduled__2024-07-14T02:33:00+00:00 [queued]>
[2024-07-15T06:40:07.943+0000] {taskinstance.py:2076} INFO - Dependencies all met for dep_context=requeueable deps ti=<TaskInstance: fetch_spread_values.fetch_and_compute_spread_btc_mxn scheduled__2024-07-14T02:33:00+00:00 [queued]>
[2024-07-15T06:40:07.943+0000] {taskinstance.py:2306} INFO - Starting attempt 1 of 2
[2024-07-15T06:40:08.018+0000] {taskinstance.py:2330} INFO - Executing <Task(PythonOperator): fetch_and_compute_spread_btc_mxn> on 2024-07-14 02:33:00+00:00
[2024-07-15T06:40:08.022+0000] {logging_mixin.py:188} WARNING - /home/***/.local/lib/python3.12/site-packages/***/task/task_runner/standard_task_runner.py:61 DeprecationWarning: This process (pid=4488) is multi-threaded, use of fork() may lead to deadlocks in the child.
[2024-07-15T06:40:08.025+0000] {standard_task_runner.py:63} INFO - Started process 4498 to run task
[2024-07-15T06:40:08.023+0000] {standard_task_runner.py:90} INFO - Running: ['***', 'tasks', 'run', 'fetch_spread_values', 'fetch_and_compute_spread_btc_mxn', 'scheduled__2024-07-14T02:33:00+00:00', '--job-id', '901', '--raw', '--subdir', 'DAGS_FOLDER/et_dag.py', '--cfg-path', '/tmp/tmpk1uwbaiu']
[2024-07-15T06:40:08.027+0000] {standard_task_runner.py:91} INFO - Job 901: Subtask fetch_and_compute_spread_btc_mxn
[2024-07-15T06:40:08.075+0000] {task_command.py:426} INFO - Running <TaskInstance: fetch_spread_values.fetch_and_compute_spread_btc_mxn scheduled__2024-07-14T02:33:00+00:00 [running]> on host 52e7a9c3d832
[2024-07-15T06:40:08.176+0000] {taskinstance.py:2648} INFO - Exporting env vars: AIRFLOW_CTX_DAG_OWNER='***' AIRFLOW_CTX_DAG_ID='fetch_spread_values' AIRFLOW_CTX_TASK_ID='fetch_and_compute_spread_btc_mxn' AIRFLOW_CTX_EXECUTION_DATE='2024-07-14T02:33:00+00:00' AIRFLOW_CTX_TRY_NUMBER='1' AIRFLOW_CTX_DAG_RUN_ID='scheduled__2024-07-14T02:33:00+00:00'
[2024-07-15T06:40:08.178+0000] {taskinstance.py:430} INFO - ::endgroup::
[2024-07-15T06:40:08.353+0000] {et_dag.py:27} INFO - Data fetched for book btc_mxn
[2024-07-15T06:40:08.354+0000] {et_dag.py:28} INFO - {'success': True, 'payload': {'high': '1119480.00', 'last': '1119480.00', 'created_at': '2024-07-15T06:40:07+00:00', 'book': 'btc_mxn', 'volume': '0', 'vwap': '0', 'low': '1119480.00', 'ask': '1023070.02', 'bid': '1023069.98', 'change_24': '0.00', 'rolling_average_change': {}}}
[2024-07-15T06:40:08.355+0000] {et_dag.py:31} INFO - Spread computed
[2024-07-15T06:40:08.356+0000] {et_dag.py:32} INFO - {'orderbook_timestamp': '2024-07-15T06:40:07+00:00', 'book': 'btc_mxn', 'bid': 1023069.98, 'ask': 1023070.02, 'spread': 3.909800820598076e-06}
[2024-07-15T06:40:08.357+0000] {taskinstance.py:441} INFO - ::group::Post task execution logs
[2024-07-15T06:40:08.358+0000] {taskinstance.py:2905} ERROR - Task failed with exception
Traceback (most recent call last):
  File "/home/airflow/.local/lib/python3.12/site-packages/urllib3/connection.py", line 196, in _new_conn
    sock = connection.create_connection(
           ^^^^^^^^^^^^^^^^^^^^^^^^^^^^^
  File "/home/airflow/.local/lib/python3.12/site-packages/urllib3/util/connection.py", line 85, in create_connection
    raise err
  File "/home/airflow/.local/lib/python3.12/site-packages/urllib3/util/connection.py", line 73, in create_connection
    sock.connect(sa)
ConnectionRefusedError: [Errno 111] Connection refused

The above exception was the direct cause of the following exception:

Traceback (most recent call last):
  File "/home/airflow/.local/lib/python3.12/site-packages/urllib3/connectionpool.py", line 789, in urlopen
    response = self._make_request(
               ^^^^^^^^^^^^^^^^^^^
  File "/home/airflow/.local/lib/python3.12/site-packages/urllib3/connectionpool.py", line 495, in _make_request
    conn.request(
  File "/home/airflow/.local/lib/python3.12/site-packages/urllib3/connection.py", line 398, in request
    self.endheaders()
  File "/usr/local/lib/python3.12/http/client.py", line 1331, in endheaders
    self._send_output(message_body, encode_chunked=encode_chunked)
  File "/usr/local/lib/python3.12/http/client.py", line 1091, in _send_output
    self.send(msg)
  File "/usr/local/lib/python3.12/http/client.py", line 1035, in send
    self.connect()
  File "/home/airflow/.local/lib/python3.12/site-packages/urllib3/connection.py", line 236, in connect
    self.sock = self._new_conn()
                ^^^^^^^^^^^^^^^^
  File "/home/airflow/.local/lib/python3.12/site-packages/urllib3/connection.py", line 211, in _new_conn
    raise NewConnectionError(
urllib3.exceptions.NewConnectionError: <urllib3.connection.HTTPConnection object at 0xffff7bf9f7a0>: Failed to establish a new connection: [Errno 111] Connection refused

The above exception was the direct cause of the following exception:

Traceback (most recent call last):
  File "/home/airflow/.local/lib/python3.12/site-packages/requests/adapters.py", line 486, in send
    resp = conn.urlopen(
           ^^^^^^^^^^^^^
  File "/home/airflow/.local/lib/python3.12/site-packages/urllib3/connectionpool.py", line 843, in urlopen
    retries = retries.increment(
              ^^^^^^^^^^^^^^^^^^
  File "/home/airflow/.local/lib/python3.12/site-packages/urllib3/util/retry.py", line 519, in increment
    raise MaxRetryError(_pool, url, reason) from reason  # type: ignore[arg-type]
    ^^^^^^^^^^^^^^^^^^^^^^^^^^^^^^^^^^^^^^^^^^^^^^^^^^^
urllib3.exceptions.MaxRetryError: HTTPConnectionPool(host='127.0.0.1', port=8000): Max retries exceeded with url: /store_spread (Caused by NewConnectionError('<urllib3.connection.HTTPConnection object at 0xffff7bf9f7a0>: Failed to establish a new connection: [Errno 111] Connection refused'))

During handling of the above exception, another exception occurred:

Traceback (most recent call last):
  File "/home/airflow/.local/lib/python3.12/site-packages/airflow/models/taskinstance.py", line 465, in _execute_task
    result = _execute_callable(context=context, **execute_callable_kwargs)
             ^^^^^^^^^^^^^^^^^^^^^^^^^^^^^^^^^^^^^^^^^^^^^^^^^^^^^^^^^^^^^
  File "/home/airflow/.local/lib/python3.12/site-packages/airflow/models/taskinstance.py", line 432, in _execute_callable
    return execute_callable(context=context, **execute_callable_kwargs)
           ^^^^^^^^^^^^^^^^^^^^^^^^^^^^^^^^^^^^^^^^^^^^^^^^^^^^^^^^^^^^
  File "/home/airflow/.local/lib/python3.12/site-packages/airflow/models/baseoperator.py", line 401, in wrapper
    return func(self, *args, **kwargs)
           ^^^^^^^^^^^^^^^^^^^^^^^^^^^
  File "/home/airflow/.local/lib/python3.12/site-packages/airflow/operators/python.py", line 235, in execute
    return_value = self.execute_callable()
                   ^^^^^^^^^^^^^^^^^^^^^^^
  File "/home/airflow/.local/lib/python3.12/site-packages/airflow/operators/python.py", line 252, in execute_callable
    return self.python_callable(*self.op_args, **self.op_kwargs)
           ^^^^^^^^^^^^^^^^^^^^^^^^^^^^^^^^^^^^^^^^^^^^^^^^^^^^^
  File "/opt/airflow/dags/et_dag.py", line 34, in trigger_fetch_and_compute
    response = requests.post(URL_STORE_RECORD, headers=HEADERS_JSON, json=spread_record)
               ^^^^^^^^^^^^^^^^^^^^^^^^^^^^^^^^^^^^^^^^^^^^^^^^^^^^^^^^^^^^^^^^^^^^^^^^^
  File "/home/airflow/.local/lib/python3.12/site-packages/requests/api.py", line 115, in post
    return request("post", url, data=data, json=json, **kwargs)
           ^^^^^^^^^^^^^^^^^^^^^^^^^^^^^^^^^^^^^^^^^^^^^^^^^^^^
  File "/home/airflow/.local/lib/python3.12/site-packages/requests/api.py", line 59, in request
    return session.request(method=method, url=url, **kwargs)
           ^^^^^^^^^^^^^^^^^^^^^^^^^^^^^^^^^^^^^^^^^^^^^^^^^
  File "/home/airflow/.local/lib/python3.12/site-packages/requests/sessions.py", line 589, in request
    resp = self.send(prep, **send_kwargs)
           ^^^^^^^^^^^^^^^^^^^^^^^^^^^^^^
  File "/home/airflow/.local/lib/python3.12/site-packages/requests/sessions.py", line 703, in send
    r = adapter.send(request, **kwargs)
        ^^^^^^^^^^^^^^^^^^^^^^^^^^^^^^^
  File "/home/airflow/.local/lib/python3.12/site-packages/requests/adapters.py", line 519, in send
    raise ConnectionError(e, request=request)
requests.exceptions.ConnectionError: HTTPConnectionPool(host='127.0.0.1', port=8000): Max retries exceeded with url: /store_spread (Caused by NewConnectionError('<urllib3.connection.HTTPConnection object at 0xffff7bf9f7a0>: Failed to establish a new connection: [Errno 111] Connection refused'))
[2024-07-15T06:40:08.377+0000] {taskinstance.py:1206} INFO - Marking task as UP_FOR_RETRY. dag_id=fetch_spread_values, task_id=fetch_and_compute_spread_btc_mxn, run_id=scheduled__2024-07-14T02:33:00+00:00, execution_date=20240714T023300, start_date=20240715T064007, end_date=20240715T064008
[2024-07-15T06:40:08.387+0000] {standard_task_runner.py:110} ERROR - Failed to execute job 901 for task fetch_and_compute_spread_btc_mxn (HTTPConnectionPool(host='127.0.0.1', port=8000): Max retries exceeded with url: /store_spread (Caused by NewConnectionError('<urllib3.connection.HTTPConnection object at 0xffff7bf9f7a0>: Failed to establish a new connection: [Errno 111] Connection refused')); 4498)
[2024-07-15T06:40:08.415+0000] {local_task_job_runner.py:240} INFO - Task exited with return code 1
[2024-07-15T06:40:08.432+0000] {taskinstance.py:3503} INFO - 0 downstream tasks scheduled from follow-on schedule check
[2024-07-15T06:40:08.436+0000] {local_task_job_runner.py:222} INFO - ::endgroup::
