[2024-07-14T09:00:31.558+0000] {local_task_job_runner.py:120} INFO - ::group::Pre task execution logs
[2024-07-14T09:00:31.607+0000] {taskinstance.py:2076} INFO - Dependencies all met for dep_context=non-requeueable deps ti=<TaskInstance: fetch_spread_values.fetch_and_compute_spread_usd_mxn scheduled__2024-07-14T03:53:00+00:00 [queued]>
[2024-07-14T09:00:31.640+0000] {taskinstance.py:2076} INFO - Dependencies all met for dep_context=requeueable deps ti=<TaskInstance: fetch_spread_values.fetch_and_compute_spread_usd_mxn scheduled__2024-07-14T03:53:00+00:00 [queued]>
[2024-07-14T09:00:31.649+0000] {taskinstance.py:2306} INFO - Starting attempt 1 of 2
[2024-07-14T09:00:31.778+0000] {taskinstance.py:2330} INFO - Executing <Task(PythonOperator): fetch_and_compute_spread_usd_mxn> on 2024-07-14 03:53:00+00:00
[2024-07-14T09:00:31.795+0000] {warnings.py:112} WARNING - /home/***/.local/lib/python3.12/site-packages/***/task/task_runner/standard_task_runner.py:61: DeprecationWarning: This process (pid=1566) is multi-threaded, use of fork() may lead to deadlocks in the child.
  pid = os.fork()

[2024-07-14T09:00:31.805+0000] {standard_task_runner.py:63} INFO - Started process 1586 to run task
[2024-07-14T09:00:31.804+0000] {standard_task_runner.py:90} INFO - Running: ['***', 'tasks', 'run', 'fetch_spread_values', 'fetch_and_compute_spread_usd_mxn', 'scheduled__2024-07-14T03:53:00+00:00', '--job-id', '495', '--raw', '--subdir', 'DAGS_FOLDER/***.py', '--cfg-path', '/tmp/tmpiakmghpj']
[2024-07-14T09:00:31.815+0000] {standard_task_runner.py:91} INFO - Job 495: Subtask fetch_and_compute_spread_usd_mxn
[2024-07-14T09:00:32.073+0000] {task_command.py:426} INFO - Running <TaskInstance: fetch_spread_values.fetch_and_compute_spread_usd_mxn scheduled__2024-07-14T03:53:00+00:00 [running]> on host d537c34a4880
[2024-07-14T09:00:32.299+0000] {taskinstance.py:2648} INFO - Exporting env vars: AIRFLOW_CTX_DAG_OWNER='***' AIRFLOW_CTX_DAG_ID='fetch_spread_values' AIRFLOW_CTX_TASK_ID='fetch_and_compute_spread_usd_mxn' AIRFLOW_CTX_EXECUTION_DATE='2024-07-14T03:53:00+00:00' AIRFLOW_CTX_TRY_NUMBER='1' AIRFLOW_CTX_DAG_RUN_ID='scheduled__2024-07-14T03:53:00+00:00'
[2024-07-14T09:00:32.312+0000] {taskinstance.py:430} INFO - ::endgroup::
[2024-07-14T09:00:32.787+0000] {python.py:237} INFO - Done. Returned value was: None
[2024-07-14T09:00:32.815+0000] {taskinstance.py:441} INFO - ::group::Post task execution logs
[2024-07-14T09:00:32.856+0000] {taskinstance.py:1206} INFO - Marking task as SUCCESS. dag_id=fetch_spread_values, task_id=fetch_and_compute_spread_usd_mxn, run_id=scheduled__2024-07-14T03:53:00+00:00, execution_date=20240714T035300, start_date=20240714T090031, end_date=20240714T090032
[2024-07-14T09:00:32.929+0000] {local_task_job_runner.py:240} INFO - Task exited with return code 0
[2024-07-14T09:00:33.013+0000] {taskinstance.py:3503} INFO - 0 downstream tasks scheduled from follow-on schedule check
[2024-07-14T09:00:33.016+0000] {local_task_job_runner.py:222} INFO - ::endgroup::
[2024-07-14T20:33:46.594+0000] {local_task_job_runner.py:120} INFO - ::group::Pre task execution logs
[2024-07-14T20:33:46.614+0000] {taskinstance.py:2076} INFO - Dependencies all met for dep_context=non-requeueable deps ti=<TaskInstance: fetch_spread_values.fetch_and_compute_spread_usd_mxn scheduled__2024-07-14T03:53:00+00:00 [queued]>
[2024-07-14T20:33:46.619+0000] {taskinstance.py:2076} INFO - Dependencies all met for dep_context=requeueable deps ti=<TaskInstance: fetch_spread_values.fetch_and_compute_spread_usd_mxn scheduled__2024-07-14T03:53:00+00:00 [queued]>
[2024-07-14T20:33:46.620+0000] {taskinstance.py:2306} INFO - Starting attempt 1 of 2
[2024-07-14T20:33:46.628+0000] {taskinstance.py:2330} INFO - Executing <Task(PythonOperator): fetch_and_compute_spread_usd_mxn> on 2024-07-14 03:53:00+00:00
[2024-07-14T20:33:46.631+0000] {logging_mixin.py:188} WARNING - /home/***/.local/lib/python3.12/site-packages/***/task/task_runner/standard_task_runner.py:61 DeprecationWarning: This process (pid=1133) is multi-threaded, use of fork() may lead to deadlocks in the child.
[2024-07-14T20:33:46.633+0000] {standard_task_runner.py:63} INFO - Started process 1140 to run task
[2024-07-14T20:33:46.632+0000] {standard_task_runner.py:90} INFO - Running: ['***', 'tasks', 'run', 'fetch_spread_values', 'fetch_and_compute_spread_usd_mxn', 'scheduled__2024-07-14T03:53:00+00:00', '--job-id', '472', '--raw', '--subdir', 'DAGS_FOLDER/***.py', '--cfg-path', '/tmp/tmpyn6z5x49']
[2024-07-14T20:33:46.636+0000] {standard_task_runner.py:91} INFO - Job 472: Subtask fetch_and_compute_spread_usd_mxn
[2024-07-14T20:33:46.671+0000] {task_command.py:426} INFO - Running <TaskInstance: fetch_spread_values.fetch_and_compute_spread_usd_mxn scheduled__2024-07-14T03:53:00+00:00 [running]> on host 77caf7e4b282
[2024-07-14T20:33:46.725+0000] {taskinstance.py:2648} INFO - Exporting env vars: AIRFLOW_CTX_DAG_OWNER='***' AIRFLOW_CTX_DAG_ID='fetch_spread_values' AIRFLOW_CTX_TASK_ID='fetch_and_compute_spread_usd_mxn' AIRFLOW_CTX_EXECUTION_DATE='2024-07-14T03:53:00+00:00' AIRFLOW_CTX_TRY_NUMBER='1' AIRFLOW_CTX_DAG_RUN_ID='scheduled__2024-07-14T03:53:00+00:00'
[2024-07-14T20:33:46.725+0000] {taskinstance.py:430} INFO - ::endgroup::
[2024-07-14T20:33:46.896+0000] {python.py:237} INFO - Done. Returned value was: None
[2024-07-14T20:33:46.897+0000] {taskinstance.py:441} INFO - ::group::Post task execution logs
[2024-07-14T20:33:46.902+0000] {taskinstance.py:1206} INFO - Marking task as SUCCESS. dag_id=fetch_spread_values, task_id=fetch_and_compute_spread_usd_mxn, run_id=scheduled__2024-07-14T03:53:00+00:00, execution_date=20240714T035300, start_date=20240714T203346, end_date=20240714T203346
[2024-07-14T20:33:46.939+0000] {local_task_job_runner.py:240} INFO - Task exited with return code 0
[2024-07-14T20:33:46.950+0000] {taskinstance.py:3503} INFO - 0 downstream tasks scheduled from follow-on schedule check
[2024-07-14T20:33:46.951+0000] {local_task_job_runner.py:222} INFO - ::endgroup::
[2024-07-15T06:45:34.569+0000] {local_task_job_runner.py:120} INFO - ::group::Pre task execution logs
[2024-07-15T06:45:34.587+0000] {taskinstance.py:2076} INFO - Dependencies all met for dep_context=non-requeueable deps ti=<TaskInstance: fetch_spread_values.fetch_and_compute_spread_usd_mxn scheduled__2024-07-14T03:53:00+00:00 [queued]>
[2024-07-15T06:45:34.592+0000] {taskinstance.py:2076} INFO - Dependencies all met for dep_context=requeueable deps ti=<TaskInstance: fetch_spread_values.fetch_and_compute_spread_usd_mxn scheduled__2024-07-14T03:53:00+00:00 [queued]>
[2024-07-15T06:45:34.594+0000] {taskinstance.py:2306} INFO - Starting attempt 1 of 2
[2024-07-15T06:45:34.642+0000] {taskinstance.py:2330} INFO - Executing <Task(PythonOperator): fetch_and_compute_spread_usd_mxn> on 2024-07-14 03:53:00+00:00
[2024-07-15T06:45:34.647+0000] {logging_mixin.py:188} WARNING - /home/***/.local/lib/python3.12/site-packages/***/task/task_runner/standard_task_runner.py:61 DeprecationWarning: This process (pid=5381) is multi-threaded, use of fork() may lead to deadlocks in the child.
[2024-07-15T06:45:34.647+0000] {standard_task_runner.py:90} INFO - Running: ['***', 'tasks', 'run', 'fetch_spread_values', 'fetch_and_compute_spread_usd_mxn', 'scheduled__2024-07-14T03:53:00+00:00', '--job-id', '1291', '--raw', '--subdir', 'DAGS_FOLDER/et_dag.py', '--cfg-path', '/tmp/tmpnxo6d6wb']
[2024-07-15T06:45:34.654+0000] {standard_task_runner.py:91} INFO - Job 1291: Subtask fetch_and_compute_spread_usd_mxn
[2024-07-15T06:45:34.653+0000] {standard_task_runner.py:63} INFO - Started process 5385 to run task
[2024-07-15T06:45:34.697+0000] {task_command.py:426} INFO - Running <TaskInstance: fetch_spread_values.fetch_and_compute_spread_usd_mxn scheduled__2024-07-14T03:53:00+00:00 [running]> on host 52e7a9c3d832
[2024-07-15T06:45:34.764+0000] {taskinstance.py:2648} INFO - Exporting env vars: AIRFLOW_CTX_DAG_OWNER='***' AIRFLOW_CTX_DAG_ID='fetch_spread_values' AIRFLOW_CTX_TASK_ID='fetch_and_compute_spread_usd_mxn' AIRFLOW_CTX_EXECUTION_DATE='2024-07-14T03:53:00+00:00' AIRFLOW_CTX_TRY_NUMBER='1' AIRFLOW_CTX_DAG_RUN_ID='scheduled__2024-07-14T03:53:00+00:00'
[2024-07-15T06:45:34.765+0000] {taskinstance.py:430} INFO - ::endgroup::
[2024-07-15T06:45:34.953+0000] {et_dag.py:27} INFO - Data fetched for book usd_mxn
[2024-07-15T06:45:34.955+0000] {et_dag.py:28} INFO - {'success': True, 'payload': {'high': '18.34', 'last': '18.34', 'created_at': '2024-07-15T06:45:34+00:00', 'book': 'usd_mxn', 'volume': '0', 'vwap': '0', 'low': '18.34', 'ask': '17.61', 'bid': '17.60', 'change_24': '0.00', 'rolling_average_change': {}}}
[2024-07-15T06:45:34.956+0000] {et_dag.py:31} INFO - Spread computed
[2024-07-15T06:45:34.961+0000] {et_dag.py:32} INFO - {'orderbook_timestamp': '2024-07-15T06:45:34+00:00', 'book': 'usd_mxn', 'bid': 17.6, 'ask': 17.61, 'spread': 0.05678591709254975}
[2024-07-15T06:45:34.963+0000] {taskinstance.py:441} INFO - ::group::Post task execution logs
[2024-07-15T06:45:34.965+0000] {taskinstance.py:2905} ERROR - Task failed with exception
Traceback (most recent call last):
  File "/home/airflow/.local/lib/python3.12/site-packages/urllib3/connection.py", line 196, in _new_conn
    sock = connection.create_connection(
           ^^^^^^^^^^^^^^^^^^^^^^^^^^^^^
  File "/home/airflow/.local/lib/python3.12/site-packages/urllib3/util/connection.py", line 85, in create_connection
    raise err
  File "/home/airflow/.local/lib/python3.12/site-packages/urllib3/util/connection.py", line 73, in create_connection
    sock.connect(sa)
ConnectionRefusedError: [Errno 111] Connection refused

The above exception was the direct cause of the following exception:

Traceback (most recent call last):
  File "/home/airflow/.local/lib/python3.12/site-packages/urllib3/connectionpool.py", line 789, in urlopen
    response = self._make_request(
               ^^^^^^^^^^^^^^^^^^^
  File "/home/airflow/.local/lib/python3.12/site-packages/urllib3/connectionpool.py", line 495, in _make_request
    conn.request(
  File "/home/airflow/.local/lib/python3.12/site-packages/urllib3/connection.py", line 398, in request
    self.endheaders()
  File "/usr/local/lib/python3.12/http/client.py", line 1331, in endheaders
    self._send_output(message_body, encode_chunked=encode_chunked)
  File "/usr/local/lib/python3.12/http/client.py", line 1091, in _send_output
    self.send(msg)
  File "/usr/local/lib/python3.12/http/client.py", line 1035, in send
    self.connect()
  File "/home/airflow/.local/lib/python3.12/site-packages/urllib3/connection.py", line 236, in connect
    self.sock = self._new_conn()
                ^^^^^^^^^^^^^^^^
  File "/home/airflow/.local/lib/python3.12/site-packages/urllib3/connection.py", line 211, in _new_conn
    raise NewConnectionError(
urllib3.exceptions.NewConnectionError: <urllib3.connection.HTTPConnection object at 0xffff7bf9f7a0>: Failed to establish a new connection: [Errno 111] Connection refused

The above exception was the direct cause of the following exception:

Traceback (most recent call last):
  File "/home/airflow/.local/lib/python3.12/site-packages/requests/adapters.py", line 486, in send
    resp = conn.urlopen(
           ^^^^^^^^^^^^^
  File "/home/airflow/.local/lib/python3.12/site-packages/urllib3/connectionpool.py", line 843, in urlopen
    retries = retries.increment(
              ^^^^^^^^^^^^^^^^^^
  File "/home/airflow/.local/lib/python3.12/site-packages/urllib3/util/retry.py", line 519, in increment
    raise MaxRetryError(_pool, url, reason) from reason  # type: ignore[arg-type]
    ^^^^^^^^^^^^^^^^^^^^^^^^^^^^^^^^^^^^^^^^^^^^^^^^^^^
urllib3.exceptions.MaxRetryError: HTTPConnectionPool(host='127.0.0.1', port=8000): Max retries exceeded with url: /store_spread (Caused by NewConnectionError('<urllib3.connection.HTTPConnection object at 0xffff7bf9f7a0>: Failed to establish a new connection: [Errno 111] Connection refused'))

During handling of the above exception, another exception occurred:

Traceback (most recent call last):
  File "/home/airflow/.local/lib/python3.12/site-packages/airflow/models/taskinstance.py", line 465, in _execute_task
    result = _execute_callable(context=context, **execute_callable_kwargs)
             ^^^^^^^^^^^^^^^^^^^^^^^^^^^^^^^^^^^^^^^^^^^^^^^^^^^^^^^^^^^^^
  File "/home/airflow/.local/lib/python3.12/site-packages/airflow/models/taskinstance.py", line 432, in _execute_callable
    return execute_callable(context=context, **execute_callable_kwargs)
           ^^^^^^^^^^^^^^^^^^^^^^^^^^^^^^^^^^^^^^^^^^^^^^^^^^^^^^^^^^^^
  File "/home/airflow/.local/lib/python3.12/site-packages/airflow/models/baseoperator.py", line 401, in wrapper
    return func(self, *args, **kwargs)
           ^^^^^^^^^^^^^^^^^^^^^^^^^^^
  File "/home/airflow/.local/lib/python3.12/site-packages/airflow/operators/python.py", line 235, in execute
    return_value = self.execute_callable()
                   ^^^^^^^^^^^^^^^^^^^^^^^
  File "/home/airflow/.local/lib/python3.12/site-packages/airflow/operators/python.py", line 252, in execute_callable
    return self.python_callable(*self.op_args, **self.op_kwargs)
           ^^^^^^^^^^^^^^^^^^^^^^^^^^^^^^^^^^^^^^^^^^^^^^^^^^^^^
  File "/opt/airflow/dags/et_dag.py", line 34, in trigger_fetch_and_compute
    response = requests.post(URL_STORE_RECORD, headers=HEADERS_JSON, json=spread_record)
               ^^^^^^^^^^^^^^^^^^^^^^^^^^^^^^^^^^^^^^^^^^^^^^^^^^^^^^^^^^^^^^^^^^^^^^^^^
  File "/home/airflow/.local/lib/python3.12/site-packages/requests/api.py", line 115, in post
    return request("post", url, data=data, json=json, **kwargs)
           ^^^^^^^^^^^^^^^^^^^^^^^^^^^^^^^^^^^^^^^^^^^^^^^^^^^^
  File "/home/airflow/.local/lib/python3.12/site-packages/requests/api.py", line 59, in request
    return session.request(method=method, url=url, **kwargs)
           ^^^^^^^^^^^^^^^^^^^^^^^^^^^^^^^^^^^^^^^^^^^^^^^^^
  File "/home/airflow/.local/lib/python3.12/site-packages/requests/sessions.py", line 589, in request
    resp = self.send(prep, **send_kwargs)
           ^^^^^^^^^^^^^^^^^^^^^^^^^^^^^^
  File "/home/airflow/.local/lib/python3.12/site-packages/requests/sessions.py", line 703, in send
    r = adapter.send(request, **kwargs)
        ^^^^^^^^^^^^^^^^^^^^^^^^^^^^^^^
  File "/home/airflow/.local/lib/python3.12/site-packages/requests/adapters.py", line 519, in send
    raise ConnectionError(e, request=request)
requests.exceptions.ConnectionError: HTTPConnectionPool(host='127.0.0.1', port=8000): Max retries exceeded with url: /store_spread (Caused by NewConnectionError('<urllib3.connection.HTTPConnection object at 0xffff7bf9f7a0>: Failed to establish a new connection: [Errno 111] Connection refused'))
[2024-07-15T06:45:34.991+0000] {taskinstance.py:1206} INFO - Marking task as UP_FOR_RETRY. dag_id=fetch_spread_values, task_id=fetch_and_compute_spread_usd_mxn, run_id=scheduled__2024-07-14T03:53:00+00:00, execution_date=20240714T035300, start_date=20240715T064534, end_date=20240715T064534
[2024-07-15T06:45:35.004+0000] {standard_task_runner.py:110} ERROR - Failed to execute job 1291 for task fetch_and_compute_spread_usd_mxn (HTTPConnectionPool(host='127.0.0.1', port=8000): Max retries exceeded with url: /store_spread (Caused by NewConnectionError('<urllib3.connection.HTTPConnection object at 0xffff7bf9f7a0>: Failed to establish a new connection: [Errno 111] Connection refused')); 5385)
[2024-07-15T06:45:35.050+0000] {local_task_job_runner.py:240} INFO - Task exited with return code 1
[2024-07-15T06:45:35.071+0000] {taskinstance.py:3503} INFO - 0 downstream tasks scheduled from follow-on schedule check
[2024-07-15T06:45:35.080+0000] {local_task_job_runner.py:222} INFO - ::endgroup::
