[2024-07-14T22:00:00.394+0000] {local_task_job_runner.py:120} INFO - ::group::Pre task execution logs
[2024-07-14T22:00:00.422+0000] {taskinstance.py:2076} INFO - Dependencies all met for dep_context=non-requeueable deps ti=<TaskInstance: save_spread_values.save_and_flush_task scheduled__2024-07-14T21:50:00+00:00 [queued]>
[2024-07-14T22:00:00.426+0000] {taskinstance.py:2076} INFO - Dependencies all met for dep_context=requeueable deps ti=<TaskInstance: save_spread_values.save_and_flush_task scheduled__2024-07-14T21:50:00+00:00 [queued]>
[2024-07-14T22:00:00.427+0000] {taskinstance.py:2306} INFO - Starting attempt 1 of 2
[2024-07-14T22:00:00.434+0000] {taskinstance.py:2330} INFO - Executing <Task(PythonOperator): save_and_flush_task> on 2024-07-14 21:50:00+00:00
[2024-07-14T22:00:00.439+0000] {logging_mixin.py:188} WARNING - /home/***/.local/lib/python3.12/site-packages/***/task/task_runner/standard_task_runner.py:61 DeprecationWarning: This process (pid=7323) is multi-threaded, use of fork() may lead to deadlocks in the child.
[2024-07-14T22:00:00.441+0000] {standard_task_runner.py:63} INFO - Started process 7327 to run task
[2024-07-14T22:00:00.441+0000] {standard_task_runner.py:90} INFO - Running: ['***', 'tasks', 'run', 'save_spread_values', 'save_and_flush_task', 'scheduled__2024-07-14T21:50:00+00:00', '--job-id', '2795', '--raw', '--subdir', 'DAGS_FOLDER/et_dag.py', '--cfg-path', '/tmp/tmp3tyoiyr7']
[2024-07-14T22:00:00.443+0000] {standard_task_runner.py:91} INFO - Job 2795: Subtask save_and_flush_task
[2024-07-14T22:00:00.494+0000] {task_command.py:426} INFO - Running <TaskInstance: save_spread_values.save_and_flush_task scheduled__2024-07-14T21:50:00+00:00 [running]> on host 77caf7e4b282
[2024-07-14T22:00:00.558+0000] {taskinstance.py:2648} INFO - Exporting env vars: AIRFLOW_CTX_DAG_OWNER='***' AIRFLOW_CTX_DAG_ID='save_spread_values' AIRFLOW_CTX_TASK_ID='save_and_flush_task' AIRFLOW_CTX_EXECUTION_DATE='2024-07-14T21:50:00+00:00' AIRFLOW_CTX_TRY_NUMBER='1' AIRFLOW_CTX_DAG_RUN_ID='scheduled__2024-07-14T21:50:00+00:00'
[2024-07-14T22:00:00.559+0000] {taskinstance.py:430} INFO - ::endgroup::
[2024-07-14T22:00:00.569+0000] {et_dag.py:34} INFO - Rows to be saved: 0 in /opt/***
[2024-07-14T22:00:00.570+0000] {et_dag.py:35} INFO - ['logs', 'dags', 'jobs', '***.cfg']
[2024-07-14T22:00:00.570+0000] {python.py:237} INFO - Done. Returned value was: None
[2024-07-14T22:00:00.571+0000] {taskinstance.py:441} INFO - ::group::Post task execution logs
[2024-07-14T22:00:00.579+0000] {taskinstance.py:1206} INFO - Marking task as SUCCESS. dag_id=save_spread_values, task_id=save_and_flush_task, run_id=scheduled__2024-07-14T21:50:00+00:00, execution_date=20240714T215000, start_date=20240714T220000, end_date=20240714T220000
[2024-07-14T22:00:00.623+0000] {local_task_job_runner.py:240} INFO - Task exited with return code 0
[2024-07-14T22:00:00.635+0000] {taskinstance.py:3503} INFO - 0 downstream tasks scheduled from follow-on schedule check
[2024-07-14T22:00:00.636+0000] {local_task_job_runner.py:222} INFO - ::endgroup::
[2024-07-15T06:39:01.767+0000] {local_task_job_runner.py:120} INFO - ::group::Pre task execution logs
[2024-07-15T06:39:01.821+0000] {taskinstance.py:2076} INFO - Dependencies all met for dep_context=non-requeueable deps ti=<TaskInstance: save_spread_values.save_and_flush_task scheduled__2024-07-14T21:50:00+00:00 [queued]>
[2024-07-15T06:39:01.829+0000] {taskinstance.py:2076} INFO - Dependencies all met for dep_context=requeueable deps ti=<TaskInstance: save_spread_values.save_and_flush_task scheduled__2024-07-14T21:50:00+00:00 [queued]>
[2024-07-15T06:39:01.834+0000] {taskinstance.py:2306} INFO - Starting attempt 1 of 2
[2024-07-15T06:39:01.855+0000] {taskinstance.py:2330} INFO - Executing <Task(PythonOperator): save_and_flush_task> on 2024-07-14 21:50:00+00:00
[2024-07-15T06:39:01.869+0000] {logging_mixin.py:188} WARNING - /home/***/.local/lib/python3.12/site-packages/***/task/task_runner/standard_task_runner.py:61 DeprecationWarning: This process (pid=4244) is multi-threaded, use of fork() may lead to deadlocks in the child.
[2024-07-15T06:39:01.875+0000] {standard_task_runner.py:63} INFO - Started process 4257 to run task
[2024-07-15T06:39:01.870+0000] {standard_task_runner.py:90} INFO - Running: ['***', 'tasks', 'run', 'save_spread_values', 'save_and_flush_task', 'scheduled__2024-07-14T21:50:00+00:00', '--job-id', '791', '--raw', '--subdir', 'DAGS_FOLDER/et_dag.py', '--cfg-path', '/tmp/tmpufoadgcn']
[2024-07-15T06:39:01.884+0000] {standard_task_runner.py:91} INFO - Job 791: Subtask save_and_flush_task
[2024-07-15T06:39:01.940+0000] {task_command.py:426} INFO - Running <TaskInstance: save_spread_values.save_and_flush_task scheduled__2024-07-14T21:50:00+00:00 [running]> on host 52e7a9c3d832
[2024-07-15T06:39:02.012+0000] {taskinstance.py:2648} INFO - Exporting env vars: AIRFLOW_CTX_DAG_OWNER='***' AIRFLOW_CTX_DAG_ID='save_spread_values' AIRFLOW_CTX_TASK_ID='save_and_flush_task' AIRFLOW_CTX_EXECUTION_DATE='2024-07-14T21:50:00+00:00' AIRFLOW_CTX_TRY_NUMBER='1' AIRFLOW_CTX_DAG_RUN_ID='scheduled__2024-07-14T21:50:00+00:00'
[2024-07-15T06:39:02.013+0000] {taskinstance.py:430} INFO - ::endgroup::
[2024-07-15T06:39:02.020+0000] {taskinstance.py:441} INFO - ::group::Post task execution logs
[2024-07-15T06:39:02.021+0000] {taskinstance.py:2905} ERROR - Task failed with exception
Traceback (most recent call last):
  File "/home/airflow/.local/lib/python3.12/site-packages/airflow/models/taskinstance.py", line 465, in _execute_task
    result = _execute_callable(context=context, **execute_callable_kwargs)
             ^^^^^^^^^^^^^^^^^^^^^^^^^^^^^^^^^^^^^^^^^^^^^^^^^^^^^^^^^^^^^
  File "/home/airflow/.local/lib/python3.12/site-packages/airflow/models/taskinstance.py", line 432, in _execute_callable
    return execute_callable(context=context, **execute_callable_kwargs)
           ^^^^^^^^^^^^^^^^^^^^^^^^^^^^^^^^^^^^^^^^^^^^^^^^^^^^^^^^^^^^
  File "/home/airflow/.local/lib/python3.12/site-packages/airflow/models/baseoperator.py", line 401, in wrapper
    return func(self, *args, **kwargs)
           ^^^^^^^^^^^^^^^^^^^^^^^^^^^
  File "/home/airflow/.local/lib/python3.12/site-packages/airflow/operators/python.py", line 235, in execute
    return_value = self.execute_callable()
                   ^^^^^^^^^^^^^^^^^^^^^^^
  File "/home/airflow/.local/lib/python3.12/site-packages/airflow/operators/python.py", line 252, in execute_callable
    return self.python_callable(*self.op_args, **self.op_kwargs)
           ^^^^^^^^^^^^^^^^^^^^^^^^^^^^^^^^^^^^^^^^^^^^^^^^^^^^^
  File "/opt/airflow/dags/et_dag.py", line 38, in trigger_save_and_flush
    logging('Invoking method to save data from records')
TypeError: 'module' object is not callable
[2024-07-15T06:39:02.030+0000] {taskinstance.py:1206} INFO - Marking task as UP_FOR_RETRY. dag_id=save_spread_values, task_id=save_and_flush_task, run_id=scheduled__2024-07-14T21:50:00+00:00, execution_date=20240714T215000, start_date=20240715T063901, end_date=20240715T063902
[2024-07-15T06:39:02.037+0000] {standard_task_runner.py:110} ERROR - Failed to execute job 791 for task save_and_flush_task ('module' object is not callable; 4257)
[2024-07-15T06:39:02.065+0000] {local_task_job_runner.py:240} INFO - Task exited with return code 1
[2024-07-15T06:39:02.079+0000] {taskinstance.py:3503} INFO - 0 downstream tasks scheduled from follow-on schedule check
[2024-07-15T06:39:02.085+0000] {local_task_job_runner.py:222} INFO - ::endgroup::
