[2024-07-15T06:40:03.086+0000] {local_task_job_runner.py:120} INFO - ::group::Pre task execution logs
[2024-07-15T06:40:03.149+0000] {taskinstance.py:2076} INFO - Dependencies all met for dep_context=non-requeueable deps ti=<TaskInstance: save_spread_values.save_and_flush_task scheduled__2024-07-14T21:20:00+00:00 [queued]>
[2024-07-15T06:40:03.163+0000] {taskinstance.py:2076} INFO - Dependencies all met for dep_context=requeueable deps ti=<TaskInstance: save_spread_values.save_and_flush_task scheduled__2024-07-14T21:20:00+00:00 [queued]>
[2024-07-15T06:40:03.168+0000] {taskinstance.py:2306} INFO - Starting attempt 2 of 2
[2024-07-15T06:40:03.201+0000] {taskinstance.py:2330} INFO - Executing <Task(PythonOperator): save_and_flush_task> on 2024-07-14 21:20:00+00:00
[2024-07-15T06:40:03.213+0000] {logging_mixin.py:188} WARNING - /home/***/.local/lib/python3.12/site-packages/***/task/task_runner/standard_task_runner.py:61 DeprecationWarning: This process (pid=4359) is multi-threaded, use of fork() may lead to deadlocks in the child.
[2024-07-15T06:40:03.221+0000] {standard_task_runner.py:63} INFO - Started process 4380 to run task
[2024-07-15T06:40:03.215+0000] {standard_task_runner.py:90} INFO - Running: ['***', 'tasks', 'run', 'save_spread_values', 'save_and_flush_task', 'scheduled__2024-07-14T21:20:00+00:00', '--job-id', '845', '--raw', '--subdir', 'DAGS_FOLDER/et_dag.py', '--cfg-path', '/tmp/tmp711q6053']
[2024-07-15T06:40:03.225+0000] {standard_task_runner.py:91} INFO - Job 845: Subtask save_and_flush_task
[2024-07-15T06:40:03.326+0000] {task_command.py:426} INFO - Running <TaskInstance: save_spread_values.save_and_flush_task scheduled__2024-07-14T21:20:00+00:00 [running]> on host 52e7a9c3d832
[2024-07-15T06:40:03.458+0000] {taskinstance.py:2648} INFO - Exporting env vars: AIRFLOW_CTX_DAG_OWNER='***' AIRFLOW_CTX_DAG_ID='save_spread_values' AIRFLOW_CTX_TASK_ID='save_and_flush_task' AIRFLOW_CTX_EXECUTION_DATE='2024-07-14T21:20:00+00:00' AIRFLOW_CTX_TRY_NUMBER='2' AIRFLOW_CTX_DAG_RUN_ID='scheduled__2024-07-14T21:20:00+00:00'
[2024-07-15T06:40:03.462+0000] {taskinstance.py:430} INFO - ::endgroup::
[2024-07-15T06:40:03.483+0000] {taskinstance.py:441} INFO - ::group::Post task execution logs
[2024-07-15T06:40:03.487+0000] {taskinstance.py:2905} ERROR - Task failed with exception
Traceback (most recent call last):
  File "/home/airflow/.local/lib/python3.12/site-packages/airflow/models/taskinstance.py", line 465, in _execute_task
    result = _execute_callable(context=context, **execute_callable_kwargs)
             ^^^^^^^^^^^^^^^^^^^^^^^^^^^^^^^^^^^^^^^^^^^^^^^^^^^^^^^^^^^^^
  File "/home/airflow/.local/lib/python3.12/site-packages/airflow/models/taskinstance.py", line 432, in _execute_callable
    return execute_callable(context=context, **execute_callable_kwargs)
           ^^^^^^^^^^^^^^^^^^^^^^^^^^^^^^^^^^^^^^^^^^^^^^^^^^^^^^^^^^^^
  File "/home/airflow/.local/lib/python3.12/site-packages/airflow/models/baseoperator.py", line 401, in wrapper
    return func(self, *args, **kwargs)
           ^^^^^^^^^^^^^^^^^^^^^^^^^^^
  File "/home/airflow/.local/lib/python3.12/site-packages/airflow/operators/python.py", line 235, in execute
    return_value = self.execute_callable()
                   ^^^^^^^^^^^^^^^^^^^^^^^
  File "/home/airflow/.local/lib/python3.12/site-packages/airflow/operators/python.py", line 252, in execute_callable
    return self.python_callable(*self.op_args, **self.op_kwargs)
           ^^^^^^^^^^^^^^^^^^^^^^^^^^^^^^^^^^^^^^^^^^^^^^^^^^^^^
  File "/opt/airflow/dags/et_dag.py", line 38, in trigger_save_and_flush
    logging('Invoking method to save data from records')
TypeError: 'module' object is not callable
[2024-07-15T06:40:03.533+0000] {taskinstance.py:1206} INFO - Marking task as FAILED. dag_id=save_spread_values, task_id=save_and_flush_task, run_id=scheduled__2024-07-14T21:20:00+00:00, execution_date=20240714T212000, start_date=20240715T064003, end_date=20240715T064003
[2024-07-15T06:40:03.562+0000] {standard_task_runner.py:110} ERROR - Failed to execute job 845 for task save_and_flush_task ('module' object is not callable; 4380)
[2024-07-15T06:40:03.578+0000] {local_task_job_runner.py:240} INFO - Task exited with return code 1
[2024-07-15T06:40:03.599+0000] {local_task_job_runner.py:222} INFO - ::endgroup::
