[2024-07-15T07:42:52.631+0000] {local_task_job_runner.py:120} INFO - ::group::Pre task execution logs
[2024-07-15T07:42:52.642+0000] {taskinstance.py:2076} INFO - Dependencies all met for dep_context=non-requeueable deps ti=<TaskInstance: post_spread_data.post_spread_task manual__2024-07-15T07:42:52.318101+00:00 [queued]>
[2024-07-15T07:42:52.647+0000] {taskinstance.py:2076} INFO - Dependencies all met for dep_context=requeueable deps ti=<TaskInstance: post_spread_data.post_spread_task manual__2024-07-15T07:42:52.318101+00:00 [queued]>
[2024-07-15T07:42:52.647+0000] {taskinstance.py:2306} INFO - Starting attempt 1 of 2
[2024-07-15T07:42:52.654+0000] {taskinstance.py:2330} INFO - Executing <Task(SimpleHttpOperator): post_spread_task> on 2024-07-15 07:42:52.318101+00:00
[2024-07-15T07:42:52.661+0000] {logging_mixin.py:188} WARNING - /home/***/.local/lib/python3.12/site-packages/***/task/task_runner/standard_task_runner.py:61 DeprecationWarning: This process (pid=1291) is multi-threaded, use of fork() may lead to deadlocks in the child.
[2024-07-15T07:42:52.660+0000] {standard_task_runner.py:90} INFO - Running: ['***', 'tasks', 'run', 'post_spread_data', 'post_spread_task', 'manual__2024-07-15T07:42:52.318101+00:00', '--job-id', '197', '--raw', '--subdir', 'DAGS_FOLDER/post_test_dag.py', '--cfg-path', '/tmp/tmpozu8f_su']
[2024-07-15T07:42:52.662+0000] {standard_task_runner.py:63} INFO - Started process 1294 to run task
[2024-07-15T07:42:52.662+0000] {standard_task_runner.py:91} INFO - Job 197: Subtask post_spread_task
[2024-07-15T07:42:52.695+0000] {task_command.py:426} INFO - Running <TaskInstance: post_spread_data.post_spread_task manual__2024-07-15T07:42:52.318101+00:00 [running]> on host 07ee111a4cec
[2024-07-15T07:42:52.744+0000] {taskinstance.py:2648} INFO - Exporting env vars: AIRFLOW_CTX_DAG_OWNER='***' AIRFLOW_CTX_DAG_ID='post_spread_data' AIRFLOW_CTX_TASK_ID='post_spread_task' AIRFLOW_CTX_EXECUTION_DATE='2024-07-15T07:42:52.318101+00:00' AIRFLOW_CTX_TRY_NUMBER='1' AIRFLOW_CTX_DAG_RUN_ID='manual__2024-07-15T07:42:52.318101+00:00'
[2024-07-15T07:42:52.745+0000] {taskinstance.py:430} INFO - ::endgroup::
[2024-07-15T07:42:52.755+0000] {http.py:169} INFO - Calling HTTP method
[2024-07-15T07:42:52.763+0000] {base.py:84} INFO - Using connection ID 'http_default' for task execution.
[2024-07-15T07:42:52.769+0000] {base.py:84} INFO - Using connection ID 'http_default' for task execution.
[2024-07-15T07:42:52.774+0000] {http.py:243} WARNING - HTTPConnectionPool(host='0.0.0.0', port=8000): Max retries exceeded with url: /store_spread (Caused by NewConnectionError('<urllib3.connection.HTTPConnection object at 0xffff89a92390>: Failed to establish a new connection: [Errno 111] Connection refused')) Tenacity will retry to execute the operation
[2024-07-15T07:42:52.774+0000] {taskinstance.py:441} INFO - ::group::Post task execution logs
[2024-07-15T07:42:52.774+0000] {taskinstance.py:2905} ERROR - Task failed with exception
Traceback (most recent call last):
  File "/home/airflow/.local/lib/python3.12/site-packages/urllib3/connection.py", line 196, in _new_conn
    sock = connection.create_connection(
           ^^^^^^^^^^^^^^^^^^^^^^^^^^^^^
  File "/home/airflow/.local/lib/python3.12/site-packages/urllib3/util/connection.py", line 85, in create_connection
    raise err
  File "/home/airflow/.local/lib/python3.12/site-packages/urllib3/util/connection.py", line 73, in create_connection
    sock.connect(sa)
ConnectionRefusedError: [Errno 111] Connection refused

The above exception was the direct cause of the following exception:

Traceback (most recent call last):
  File "/home/airflow/.local/lib/python3.12/site-packages/urllib3/connectionpool.py", line 789, in urlopen
    response = self._make_request(
               ^^^^^^^^^^^^^^^^^^^
  File "/home/airflow/.local/lib/python3.12/site-packages/urllib3/connectionpool.py", line 495, in _make_request
    conn.request(
  File "/home/airflow/.local/lib/python3.12/site-packages/urllib3/connection.py", line 398, in request
    self.endheaders()
  File "/usr/local/lib/python3.12/http/client.py", line 1331, in endheaders
    self._send_output(message_body, encode_chunked=encode_chunked)
  File "/usr/local/lib/python3.12/http/client.py", line 1091, in _send_output
    self.send(msg)
  File "/usr/local/lib/python3.12/http/client.py", line 1035, in send
    self.connect()
  File "/home/airflow/.local/lib/python3.12/site-packages/urllib3/connection.py", line 236, in connect
    self.sock = self._new_conn()
                ^^^^^^^^^^^^^^^^
  File "/home/airflow/.local/lib/python3.12/site-packages/urllib3/connection.py", line 211, in _new_conn
    raise NewConnectionError(
urllib3.exceptions.NewConnectionError: <urllib3.connection.HTTPConnection object at 0xffff89a92390>: Failed to establish a new connection: [Errno 111] Connection refused

The above exception was the direct cause of the following exception:

Traceback (most recent call last):
  File "/home/airflow/.local/lib/python3.12/site-packages/requests/adapters.py", line 486, in send
    resp = conn.urlopen(
           ^^^^^^^^^^^^^
  File "/home/airflow/.local/lib/python3.12/site-packages/urllib3/connectionpool.py", line 843, in urlopen
    retries = retries.increment(
              ^^^^^^^^^^^^^^^^^^
  File "/home/airflow/.local/lib/python3.12/site-packages/urllib3/util/retry.py", line 519, in increment
    raise MaxRetryError(_pool, url, reason) from reason  # type: ignore[arg-type]
    ^^^^^^^^^^^^^^^^^^^^^^^^^^^^^^^^^^^^^^^^^^^^^^^^^^^
urllib3.exceptions.MaxRetryError: HTTPConnectionPool(host='0.0.0.0', port=8000): Max retries exceeded with url: /store_spread (Caused by NewConnectionError('<urllib3.connection.HTTPConnection object at 0xffff89a92390>: Failed to establish a new connection: [Errno 111] Connection refused'))

During handling of the above exception, another exception occurred:

Traceback (most recent call last):
  File "/home/airflow/.local/lib/python3.12/site-packages/airflow/models/taskinstance.py", line 465, in _execute_task
    result = _execute_callable(context=context, **execute_callable_kwargs)
             ^^^^^^^^^^^^^^^^^^^^^^^^^^^^^^^^^^^^^^^^^^^^^^^^^^^^^^^^^^^^^
  File "/home/airflow/.local/lib/python3.12/site-packages/airflow/models/taskinstance.py", line 432, in _execute_callable
    return execute_callable(context=context, **execute_callable_kwargs)
           ^^^^^^^^^^^^^^^^^^^^^^^^^^^^^^^^^^^^^^^^^^^^^^^^^^^^^^^^^^^^
  File "/home/airflow/.local/lib/python3.12/site-packages/airflow/models/baseoperator.py", line 401, in wrapper
    return func(self, *args, **kwargs)
           ^^^^^^^^^^^^^^^^^^^^^^^^^^^
  File "/home/airflow/.local/lib/python3.12/site-packages/airflow/providers/http/operators/http.py", line 166, in execute
    return self.execute_sync(context=context)
           ^^^^^^^^^^^^^^^^^^^^^^^^^^^^^^^^^^
  File "/home/airflow/.local/lib/python3.12/site-packages/airflow/providers/http/operators/http.py", line 170, in execute_sync
    response = self.hook.run(self.endpoint, self.data, self.headers, self.extra_options)
               ^^^^^^^^^^^^^^^^^^^^^^^^^^^^^^^^^^^^^^^^^^^^^^^^^^^^^^^^^^^^^^^^^^^^^^^^^
  File "/home/airflow/.local/lib/python3.12/site-packages/airflow/providers/http/hooks/http.py", line 188, in run
    return self.run_and_check(session, prepped_request, extra_options)
           ^^^^^^^^^^^^^^^^^^^^^^^^^^^^^^^^^^^^^^^^^^^^^^^^^^^^^^^^^^^
  File "/home/airflow/.local/lib/python3.12/site-packages/airflow/providers/http/hooks/http.py", line 244, in run_and_check
    raise ex
  File "/home/airflow/.local/lib/python3.12/site-packages/airflow/providers/http/hooks/http.py", line 236, in run_and_check
    response = session.send(prepped_request, **send_kwargs)
               ^^^^^^^^^^^^^^^^^^^^^^^^^^^^^^^^^^^^^^^^^^^^
  File "/home/airflow/.local/lib/python3.12/site-packages/requests/sessions.py", line 703, in send
    r = adapter.send(request, **kwargs)
        ^^^^^^^^^^^^^^^^^^^^^^^^^^^^^^^
  File "/home/airflow/.local/lib/python3.12/site-packages/requests/adapters.py", line 519, in send
    raise ConnectionError(e, request=request)
requests.exceptions.ConnectionError: HTTPConnectionPool(host='0.0.0.0', port=8000): Max retries exceeded with url: /store_spread (Caused by NewConnectionError('<urllib3.connection.HTTPConnection object at 0xffff89a92390>: Failed to establish a new connection: [Errno 111] Connection refused'))
[2024-07-15T07:42:52.783+0000] {taskinstance.py:1206} INFO - Marking task as UP_FOR_RETRY. dag_id=post_spread_data, task_id=post_spread_task, run_id=manual__2024-07-15T07:42:52.318101+00:00, execution_date=20240715T074252, start_date=20240715T074252, end_date=20240715T074252
[2024-07-15T07:42:52.789+0000] {standard_task_runner.py:110} ERROR - Failed to execute job 197 for task post_spread_task (HTTPConnectionPool(host='0.0.0.0', port=8000): Max retries exceeded with url: /store_spread (Caused by NewConnectionError('<urllib3.connection.HTTPConnection object at 0xffff89a92390>: Failed to establish a new connection: [Errno 111] Connection refused')); 1294)
[2024-07-15T07:42:52.804+0000] {local_task_job_runner.py:240} INFO - Task exited with return code 1
[2024-07-15T07:42:52.814+0000] {taskinstance.py:3503} INFO - 0 downstream tasks scheduled from follow-on schedule check
[2024-07-15T07:42:52.815+0000] {local_task_job_runner.py:222} INFO - ::endgroup::
