[2024-07-14T08:57:25.939+0000] {local_task_job_runner.py:120} INFO - ::group::Pre task execution logs
[2024-07-14T08:57:25.954+0000] {taskinstance.py:2076} INFO - Dependencies all met for dep_context=non-requeueable deps ti=<TaskInstance: fetch_spread_values.fetch_and_compute_spread_btc_mxn scheduled__2024-07-14T00:40:00+00:00 [queued]>
[2024-07-14T08:57:25.963+0000] {taskinstance.py:2076} INFO - Dependencies all met for dep_context=requeueable deps ti=<TaskInstance: fetch_spread_values.fetch_and_compute_spread_btc_mxn scheduled__2024-07-14T00:40:00+00:00 [queued]>
[2024-07-14T08:57:25.967+0000] {taskinstance.py:2306} INFO - Starting attempt 1 of 2
[2024-07-14T08:57:25.980+0000] {taskinstance.py:2330} INFO - Executing <Task(PythonOperator): fetch_and_compute_spread_btc_mxn> on 2024-07-14 00:40:00+00:00
[2024-07-14T08:57:26.000+0000] {standard_task_runner.py:90} INFO - Running: ['***', 'tasks', 'run', 'fetch_spread_values', 'fetch_and_compute_spread_btc_mxn', 'scheduled__2024-07-14T00:40:00+00:00', '--job-id', '108', '--raw', '--subdir', 'DAGS_FOLDER/***.py', '--cfg-path', '/tmp/tmps6jc1oe1']
[2024-07-14T08:57:26.013+0000] {standard_task_runner.py:91} INFO - Job 108: Subtask fetch_and_compute_spread_btc_mxn
[2024-07-14T08:57:26.001+0000] {warnings.py:112} WARNING - /home/***/.local/lib/python3.12/site-packages/***/task/task_runner/standard_task_runner.py:61: DeprecationWarning: This process (pid=362) is multi-threaded, use of fork() may lead to deadlocks in the child.
  pid = os.fork()

[2024-07-14T08:57:26.019+0000] {standard_task_runner.py:63} INFO - Started process 377 to run task
[2024-07-14T08:57:26.060+0000] {task_command.py:426} INFO - Running <TaskInstance: fetch_spread_values.fetch_and_compute_spread_btc_mxn scheduled__2024-07-14T00:40:00+00:00 [running]> on host d537c34a4880
[2024-07-14T08:57:26.160+0000] {taskinstance.py:2648} INFO - Exporting env vars: AIRFLOW_CTX_DAG_OWNER='***' AIRFLOW_CTX_DAG_ID='fetch_spread_values' AIRFLOW_CTX_TASK_ID='fetch_and_compute_spread_btc_mxn' AIRFLOW_CTX_EXECUTION_DATE='2024-07-14T00:40:00+00:00' AIRFLOW_CTX_TRY_NUMBER='1' AIRFLOW_CTX_DAG_RUN_ID='scheduled__2024-07-14T00:40:00+00:00'
[2024-07-14T08:57:26.162+0000] {taskinstance.py:430} INFO - ::endgroup::
[2024-07-14T08:57:26.317+0000] {python.py:237} INFO - Done. Returned value was: None
[2024-07-14T08:57:26.318+0000] {taskinstance.py:441} INFO - ::group::Post task execution logs
[2024-07-14T08:57:26.326+0000] {taskinstance.py:1206} INFO - Marking task as SUCCESS. dag_id=fetch_spread_values, task_id=fetch_and_compute_spread_btc_mxn, run_id=scheduled__2024-07-14T00:40:00+00:00, execution_date=20240714T004000, start_date=20240714T085725, end_date=20240714T085726
[2024-07-14T08:57:26.375+0000] {local_task_job_runner.py:240} INFO - Task exited with return code 0
[2024-07-14T08:57:26.394+0000] {taskinstance.py:3503} INFO - 0 downstream tasks scheduled from follow-on schedule check
[2024-07-14T08:57:26.395+0000] {local_task_job_runner.py:222} INFO - ::endgroup::
[2024-07-14T20:32:20.314+0000] {local_task_job_runner.py:120} INFO - ::group::Pre task execution logs
[2024-07-14T20:32:20.336+0000] {taskinstance.py:2076} INFO - Dependencies all met for dep_context=non-requeueable deps ti=<TaskInstance: fetch_spread_values.fetch_and_compute_spread_btc_mxn scheduled__2024-07-14T00:40:00+00:00 [queued]>
[2024-07-14T20:32:20.341+0000] {taskinstance.py:2076} INFO - Dependencies all met for dep_context=requeueable deps ti=<TaskInstance: fetch_spread_values.fetch_and_compute_spread_btc_mxn scheduled__2024-07-14T00:40:00+00:00 [queued]>
[2024-07-14T20:32:20.344+0000] {taskinstance.py:2306} INFO - Starting attempt 1 of 2
[2024-07-14T20:32:20.364+0000] {taskinstance.py:2330} INFO - Executing <Task(PythonOperator): fetch_and_compute_spread_btc_mxn> on 2024-07-14 00:40:00+00:00
[2024-07-14T20:32:20.369+0000] {logging_mixin.py:188} WARNING - /home/***/.local/lib/python3.12/site-packages/***/task/task_runner/standard_task_runner.py:61 DeprecationWarning: This process (pid=347) is multi-threaded, use of fork() may lead to deadlocks in the child.
[2024-07-14T20:32:20.373+0000] {standard_task_runner.py:63} INFO - Started process 354 to run task
[2024-07-14T20:32:20.371+0000] {standard_task_runner.py:90} INFO - Running: ['***', 'tasks', 'run', 'fetch_spread_values', 'fetch_and_compute_spread_btc_mxn', 'scheduled__2024-07-14T00:40:00+00:00', '--job-id', '83', '--raw', '--subdir', 'DAGS_FOLDER/***.py', '--cfg-path', '/tmp/tmpt5v1q9_l']
[2024-07-14T20:32:20.383+0000] {standard_task_runner.py:91} INFO - Job 83: Subtask fetch_and_compute_spread_btc_mxn
[2024-07-14T20:32:20.450+0000] {task_command.py:426} INFO - Running <TaskInstance: fetch_spread_values.fetch_and_compute_spread_btc_mxn scheduled__2024-07-14T00:40:00+00:00 [running]> on host 77caf7e4b282
[2024-07-14T20:32:20.585+0000] {taskinstance.py:2648} INFO - Exporting env vars: AIRFLOW_CTX_DAG_OWNER='***' AIRFLOW_CTX_DAG_ID='fetch_spread_values' AIRFLOW_CTX_TASK_ID='fetch_and_compute_spread_btc_mxn' AIRFLOW_CTX_EXECUTION_DATE='2024-07-14T00:40:00+00:00' AIRFLOW_CTX_TRY_NUMBER='1' AIRFLOW_CTX_DAG_RUN_ID='scheduled__2024-07-14T00:40:00+00:00'
[2024-07-14T20:32:20.587+0000] {taskinstance.py:430} INFO - ::endgroup::
[2024-07-14T20:32:20.794+0000] {python.py:237} INFO - Done. Returned value was: None
[2024-07-14T20:32:20.801+0000] {taskinstance.py:441} INFO - ::group::Post task execution logs
[2024-07-14T20:32:20.810+0000] {taskinstance.py:1206} INFO - Marking task as SUCCESS. dag_id=fetch_spread_values, task_id=fetch_and_compute_spread_btc_mxn, run_id=scheduled__2024-07-14T00:40:00+00:00, execution_date=20240714T004000, start_date=20240714T203220, end_date=20240714T203220
[2024-07-14T20:32:20.849+0000] {local_task_job_runner.py:240} INFO - Task exited with return code 0
[2024-07-14T20:32:20.860+0000] {taskinstance.py:3503} INFO - 0 downstream tasks scheduled from follow-on schedule check
[2024-07-14T20:32:20.866+0000] {local_task_job_runner.py:222} INFO - ::endgroup::
[2024-07-15T06:32:30.022+0000] {local_task_job_runner.py:120} INFO - ::group::Pre task execution logs
[2024-07-15T06:32:30.042+0000] {taskinstance.py:2076} INFO - Dependencies all met for dep_context=non-requeueable deps ti=<TaskInstance: fetch_spread_values.fetch_and_compute_spread_btc_mxn scheduled__2024-07-14T00:40:00+00:00 [queued]>
[2024-07-15T06:32:30.048+0000] {taskinstance.py:2076} INFO - Dependencies all met for dep_context=requeueable deps ti=<TaskInstance: fetch_spread_values.fetch_and_compute_spread_btc_mxn scheduled__2024-07-14T00:40:00+00:00 [queued]>
[2024-07-15T06:32:30.048+0000] {taskinstance.py:2306} INFO - Starting attempt 1 of 2
[2024-07-15T06:32:30.063+0000] {taskinstance.py:2330} INFO - Executing <Task(PythonOperator): fetch_and_compute_spread_btc_mxn> on 2024-07-14 00:40:00+00:00
[2024-07-15T06:32:30.069+0000] {standard_task_runner.py:90} INFO - Running: ['***', 'tasks', 'run', 'fetch_spread_values', 'fetch_and_compute_spread_btc_mxn', 'scheduled__2024-07-14T00:40:00+00:00', '--job-id', '228', '--raw', '--subdir', 'DAGS_FOLDER/et_dag.py', '--cfg-path', '/tmp/tmpm10pmhw2']
[2024-07-15T06:32:30.072+0000] {logging_mixin.py:188} WARNING - /home/***/.local/lib/python3.12/site-packages/***/task/task_runner/standard_task_runner.py:61 DeprecationWarning: This process (pid=2989) is multi-threaded, use of fork() may lead to deadlocks in the child.
[2024-07-15T06:32:30.074+0000] {standard_task_runner.py:63} INFO - Started process 2997 to run task
[2024-07-15T06:32:30.074+0000] {standard_task_runner.py:91} INFO - Job 228: Subtask fetch_and_compute_spread_btc_mxn
[2024-07-15T06:32:30.151+0000] {task_command.py:426} INFO - Running <TaskInstance: fetch_spread_values.fetch_and_compute_spread_btc_mxn scheduled__2024-07-14T00:40:00+00:00 [running]> on host 52e7a9c3d832
[2024-07-15T06:32:30.258+0000] {taskinstance.py:2648} INFO - Exporting env vars: AIRFLOW_CTX_DAG_OWNER='***' AIRFLOW_CTX_DAG_ID='fetch_spread_values' AIRFLOW_CTX_TASK_ID='fetch_and_compute_spread_btc_mxn' AIRFLOW_CTX_EXECUTION_DATE='2024-07-14T00:40:00+00:00' AIRFLOW_CTX_TRY_NUMBER='1' AIRFLOW_CTX_DAG_RUN_ID='scheduled__2024-07-14T00:40:00+00:00'
[2024-07-15T06:32:30.260+0000] {taskinstance.py:430} INFO - ::endgroup::
[2024-07-15T06:32:30.456+0000] {et_dag.py:27} INFO - Data fetched for book btc_mxn
[2024-07-15T06:32:30.457+0000] {et_dag.py:28} INFO - {'success': True, 'payload': {'high': '1119480.00', 'last': '1119480.00', 'created_at': '2024-07-15T06:32:30+00:00', 'book': 'btc_mxn', 'volume': '0', 'vwap': '0', 'low': '1119480.00', 'ask': '1023070.02', 'bid': '1023069.98', 'change_24': '0.00', 'rolling_average_change': {}}}
[2024-07-15T06:32:30.461+0000] {et_dag.py:31} INFO - Spread computed
[2024-07-15T06:32:30.462+0000] {et_dag.py:32} INFO - {'orderbook_timestamp': '2024-07-15T06:32:30+00:00', 'book': 'btc_mxn', 'bid': 1023069.98, 'ask': 1023070.02, 'spread': 3.909800820598076e-06}
[2024-07-15T06:32:30.466+0000] {taskinstance.py:441} INFO - ::group::Post task execution logs
[2024-07-15T06:32:30.470+0000] {taskinstance.py:2905} ERROR - Task failed with exception
Traceback (most recent call last):
  File "/home/airflow/.local/lib/python3.12/site-packages/urllib3/connection.py", line 196, in _new_conn
    sock = connection.create_connection(
           ^^^^^^^^^^^^^^^^^^^^^^^^^^^^^
  File "/home/airflow/.local/lib/python3.12/site-packages/urllib3/util/connection.py", line 85, in create_connection
    raise err
  File "/home/airflow/.local/lib/python3.12/site-packages/urllib3/util/connection.py", line 73, in create_connection
    sock.connect(sa)
ConnectionRefusedError: [Errno 111] Connection refused

The above exception was the direct cause of the following exception:

Traceback (most recent call last):
  File "/home/airflow/.local/lib/python3.12/site-packages/urllib3/connectionpool.py", line 789, in urlopen
    response = self._make_request(
               ^^^^^^^^^^^^^^^^^^^
  File "/home/airflow/.local/lib/python3.12/site-packages/urllib3/connectionpool.py", line 495, in _make_request
    conn.request(
  File "/home/airflow/.local/lib/python3.12/site-packages/urllib3/connection.py", line 398, in request
    self.endheaders()
  File "/usr/local/lib/python3.12/http/client.py", line 1331, in endheaders
    self._send_output(message_body, encode_chunked=encode_chunked)
  File "/usr/local/lib/python3.12/http/client.py", line 1091, in _send_output
    self.send(msg)
  File "/usr/local/lib/python3.12/http/client.py", line 1035, in send
    self.connect()
  File "/home/airflow/.local/lib/python3.12/site-packages/urllib3/connection.py", line 236, in connect
    self.sock = self._new_conn()
                ^^^^^^^^^^^^^^^^
  File "/home/airflow/.local/lib/python3.12/site-packages/urllib3/connection.py", line 211, in _new_conn
    raise NewConnectionError(
urllib3.exceptions.NewConnectionError: <urllib3.connection.HTTPConnection object at 0xffff8dc742f0>: Failed to establish a new connection: [Errno 111] Connection refused

The above exception was the direct cause of the following exception:

Traceback (most recent call last):
  File "/home/airflow/.local/lib/python3.12/site-packages/requests/adapters.py", line 486, in send
    resp = conn.urlopen(
           ^^^^^^^^^^^^^
  File "/home/airflow/.local/lib/python3.12/site-packages/urllib3/connectionpool.py", line 843, in urlopen
    retries = retries.increment(
              ^^^^^^^^^^^^^^^^^^
  File "/home/airflow/.local/lib/python3.12/site-packages/urllib3/util/retry.py", line 519, in increment
    raise MaxRetryError(_pool, url, reason) from reason  # type: ignore[arg-type]
    ^^^^^^^^^^^^^^^^^^^^^^^^^^^^^^^^^^^^^^^^^^^^^^^^^^^
urllib3.exceptions.MaxRetryError: HTTPConnectionPool(host='127.0.0.1', port=8000): Max retries exceeded with url: /store_spread (Caused by NewConnectionError('<urllib3.connection.HTTPConnection object at 0xffff8dc742f0>: Failed to establish a new connection: [Errno 111] Connection refused'))

During handling of the above exception, another exception occurred:

Traceback (most recent call last):
  File "/home/airflow/.local/lib/python3.12/site-packages/airflow/models/taskinstance.py", line 465, in _execute_task
    result = _execute_callable(context=context, **execute_callable_kwargs)
             ^^^^^^^^^^^^^^^^^^^^^^^^^^^^^^^^^^^^^^^^^^^^^^^^^^^^^^^^^^^^^
  File "/home/airflow/.local/lib/python3.12/site-packages/airflow/models/taskinstance.py", line 432, in _execute_callable
    return execute_callable(context=context, **execute_callable_kwargs)
           ^^^^^^^^^^^^^^^^^^^^^^^^^^^^^^^^^^^^^^^^^^^^^^^^^^^^^^^^^^^^
  File "/home/airflow/.local/lib/python3.12/site-packages/airflow/models/baseoperator.py", line 401, in wrapper
    return func(self, *args, **kwargs)
           ^^^^^^^^^^^^^^^^^^^^^^^^^^^
  File "/home/airflow/.local/lib/python3.12/site-packages/airflow/operators/python.py", line 235, in execute
    return_value = self.execute_callable()
                   ^^^^^^^^^^^^^^^^^^^^^^^
  File "/home/airflow/.local/lib/python3.12/site-packages/airflow/operators/python.py", line 252, in execute_callable
    return self.python_callable(*self.op_args, **self.op_kwargs)
           ^^^^^^^^^^^^^^^^^^^^^^^^^^^^^^^^^^^^^^^^^^^^^^^^^^^^^
  File "/opt/airflow/dags/et_dag.py", line 34, in trigger_fetch_and_compute
    response = requests.post(URL_STORE_RECORD, headers=HEADERS_JSON, json=spread_record)
               ^^^^^^^^^^^^^^^^^^^^^^^^^^^^^^^^^^^^^^^^^^^^^^^^^^^^^^^^^^^^^^^^^^^^^^^^^
  File "/home/airflow/.local/lib/python3.12/site-packages/requests/api.py", line 115, in post
    return request("post", url, data=data, json=json, **kwargs)
           ^^^^^^^^^^^^^^^^^^^^^^^^^^^^^^^^^^^^^^^^^^^^^^^^^^^^
  File "/home/airflow/.local/lib/python3.12/site-packages/requests/api.py", line 59, in request
    return session.request(method=method, url=url, **kwargs)
           ^^^^^^^^^^^^^^^^^^^^^^^^^^^^^^^^^^^^^^^^^^^^^^^^^
  File "/home/airflow/.local/lib/python3.12/site-packages/requests/sessions.py", line 589, in request
    resp = self.send(prep, **send_kwargs)
           ^^^^^^^^^^^^^^^^^^^^^^^^^^^^^^
  File "/home/airflow/.local/lib/python3.12/site-packages/requests/sessions.py", line 703, in send
    r = adapter.send(request, **kwargs)
        ^^^^^^^^^^^^^^^^^^^^^^^^^^^^^^^
  File "/home/airflow/.local/lib/python3.12/site-packages/requests/adapters.py", line 519, in send
    raise ConnectionError(e, request=request)
requests.exceptions.ConnectionError: HTTPConnectionPool(host='127.0.0.1', port=8000): Max retries exceeded with url: /store_spread (Caused by NewConnectionError('<urllib3.connection.HTTPConnection object at 0xffff8dc742f0>: Failed to establish a new connection: [Errno 111] Connection refused'))
[2024-07-15T06:32:30.492+0000] {taskinstance.py:1206} INFO - Marking task as UP_FOR_RETRY. dag_id=fetch_spread_values, task_id=fetch_and_compute_spread_btc_mxn, run_id=scheduled__2024-07-14T00:40:00+00:00, execution_date=20240714T004000, start_date=20240715T063230, end_date=20240715T063230
[2024-07-15T06:32:30.558+0000] {standard_task_runner.py:110} ERROR - Failed to execute job 228 for task fetch_and_compute_spread_btc_mxn (HTTPConnectionPool(host='127.0.0.1', port=8000): Max retries exceeded with url: /store_spread (Caused by NewConnectionError('<urllib3.connection.HTTPConnection object at 0xffff8dc742f0>: Failed to establish a new connection: [Errno 111] Connection refused')); 2997)
[2024-07-15T06:32:30.594+0000] {local_task_job_runner.py:240} INFO - Task exited with return code 1
[2024-07-15T06:32:30.614+0000] {taskinstance.py:3503} INFO - 0 downstream tasks scheduled from follow-on schedule check
[2024-07-15T06:32:30.619+0000] {local_task_job_runner.py:222} INFO - ::endgroup::
